{
 "cells": [
  {
   "cell_type": "markdown",
   "id": "3cfa58e0-be73-4acf-a79c-e5c97ed20cc1",
   "metadata": {},
   "source": [
    "Redes Neuronais\n",
    "--------------------------"
   ]
  },
  {
   "cell_type": "code",
   "execution_count": 3,
   "id": "2e4ffac3-663e-4a90-a99f-d63a6bb7cd39",
   "metadata": {
    "tags": []
   },
   "outputs": [],
   "source": [
    "#Import Libraries\n",
    "import csv\n",
    "import pandas as pd\n",
    "import numpy as np\n",
    "import seaborn as sns\n",
    "import matplotlib.pyplot as plt\n",
    "import datetime as dt\n",
    "from datetime import datetime\n",
    "from sklearn.metrics import accuracy_score\n",
    "from sklearn.svm import SVC\n",
    "%matplotlib inline\n",
    "\n",
    "from sklearn.preprocessing import LabelEncoder\n",
    "from sklearn.tree import DecisionTreeClassifier\n",
    "from sklearn import tree\n",
    "from sklearn.model_selection import train_test_split,GridSearchCV, KFold\n",
    "from sklearn.linear_model import LinearRegression\n",
    "from sklearn.metrics import mean_squared_error, r2_score, classification_report, ConfusionMatrixDisplay\n",
    "from sklearn import metrics\n",
    "\n",
    "import tensorflow as tf\n",
    "from tensorflow import keras\n",
    "from tensorflow.keras.models import Sequential\n",
    "from tensorflow.keras.layers import Dense#, Dropout, BatchNormalization\n",
    "from scikeras.wrappers import KerasRegressor#, KerasClassifier"
   ]
  },
  {
   "cell_type": "code",
   "execution_count": 4,
   "id": "7284b09b-acba-430f-8754-1d59255b47cd",
   "metadata": {
    "tags": []
   },
   "outputs": [
    {
     "name": "stdout",
     "output_type": "stream",
     "text": [
      "TensorFlow version: 2.15.0\n"
     ]
    }
   ],
   "source": [
    "print(\"TensorFlow version:\", tf.__version__)"
   ]
  },
  {
   "cell_type": "code",
   "execution_count": 6,
   "id": "96112a60-3d51-4e3c-a3bb-ce5cb54ed0d9",
   "metadata": {
    "tags": []
   },
   "outputs": [],
   "source": [
    "train_data = pd.read_csv(\"train_data.csv\")\n",
    "test_data = pd.read_csv(\"test_data.csv\")"
   ]
  },
  {
   "cell_type": "code",
   "execution_count": 7,
   "id": "a181d964-1775-46a5-b142-c849c09be4cf",
   "metadata": {
    "tags": []
   },
   "outputs": [],
   "source": [
    "train_data['Data'] = pd.to_datetime(train_data['Data'], format='%Y-%m-%d', errors='raise')\n",
    "train_data['Data'] = train_data['Data'].map(dt.datetime.toordinal)\n",
    "\n",
    "test_data['Data'] = pd.to_datetime(test_data['Data'], format='%Y-%m-%d', errors='raise')\n",
    "test_data['Data'] = test_data['Data'].map(dt.datetime.toordinal)\n",
    "\n",
    "#merged_data_train['Data']=merged_data_train['Data'].map(dt.datetime.toordinal)"
   ]
  },
  {
   "cell_type": "code",
   "execution_count": 8,
   "id": "e8fd69e0-816e-4568-8037-e58b36898060",
   "metadata": {
    "tags": []
   },
   "outputs": [],
   "source": [
    "X = train_data.drop(['Injecao na rede (kWh)_code'], axis=1)\n",
    "y = train_data['Injecao na rede (kWh)_code']\n",
    "X_train, X_test, y_train, y_test = train_test_split(X, y, test_size=0.20479, random_state=42)"
   ]
  },
  {
   "cell_type": "code",
   "execution_count": 9,
   "id": "d32727ec-7405-4450-a183-de6f47db44fb",
   "metadata": {
    "tags": []
   },
   "outputs": [],
   "source": [
    "def build_model(activation = 'relu', learning_rate = 0.01):\n",
    "    model = Sequential()\n",
    "    model.add(Dense(16, input_dim = 5,activation = activation))\n",
    "    model.add(Dense(8, activation = activation))\n",
    "    model.add(Dense(1, activation = activation)) #output\n",
    "    #Compile the model\n",
    "    model.compile(\n",
    "        loss = 'mae',\n",
    "        optimizer = tf.optimizers.Adam(learning_rate),\n",
    "        metrics = ['mae', 'mse'])\n",
    "    return model"
   ]
  },
  {
   "cell_type": "code",
   "execution_count": 10,
   "id": "36ee449b",
   "metadata": {
    "tags": []
   },
   "outputs": [
    {
     "name": "stderr",
     "output_type": "stream",
     "text": [
      "2023-12-27 09:31:50.166074: I metal_plugin/src/device/metal_device.cc:1154] Metal device set to: Apple M1 Pro\n",
      "2023-12-27 09:31:50.166213: I metal_plugin/src/device/metal_device.cc:296] systemMemory: 16.00 GB\n",
      "2023-12-27 09:31:50.166246: I metal_plugin/src/device/metal_device.cc:313] maxCacheSize: 5.33 GB\n",
      "2023-12-27 09:31:50.166381: I tensorflow/core/common_runtime/pluggable_device/pluggable_device_factory.cc:306] Could not identify NUMA node of platform GPU ID 0, defaulting to 0. Your kernel may not have been built with NUMA support.\n",
      "2023-12-27 09:31:50.166467: I tensorflow/core/common_runtime/pluggable_device/pluggable_device_factory.cc:272] Created TensorFlow device (/job:localhost/replica:0/task:0/device:GPU:0 with 0 MB memory) -> physical PluggableDevice (device: 0, name: METAL, pci bus id: <undefined>)\n",
      "WARNING:absl:At this time, the v2.11+ optimizer `tf.keras.optimizers.Adam` runs slowly on M1/M2 Macs, please use the legacy Keras optimizer instead, located at `tf.keras.optimizers.legacy.Adam`.\n"
     ]
    },
    {
     "name": "stdout",
     "output_type": "stream",
     "text": [
      "Model: \"sequential\"\n",
      "_________________________________________________________________\n",
      " Layer (type)                Output Shape              Param #   \n",
      "=================================================================\n",
      " dense (Dense)               (None, 16)                96        \n",
      "                                                                 \n",
      " dense_1 (Dense)             (None, 8)                 136       \n",
      "                                                                 \n",
      " dense_2 (Dense)             (None, 1)                 9         \n",
      "                                                                 \n",
      "=================================================================\n",
      "Total params: 241 (964.00 Byte)\n",
      "Trainable params: 241 (964.00 Byte)\n",
      "Non-trainable params: 0 (0.00 Byte)\n",
      "_________________________________________________________________\n"
     ]
    }
   ],
   "source": [
    "model = build_model()\n",
    "model.summary()"
   ]
  },
  {
   "cell_type": "code",
   "execution_count": 8,
   "id": "19376b2e-1367-46b1-9965-7abf934a4761",
   "metadata": {
    "tags": []
   },
   "outputs": [],
   "source": [
    "optimizer = ['SGD', 'RMSprop', 'Adagrad']\n",
    "param_grid = dict(optimizer = optimizer)"
   ]
  },
  {
   "cell_type": "code",
   "execution_count": 9,
   "id": "557e4901-d121-4c6d-920f-741a60cf42d5",
   "metadata": {
    "tags": []
   },
   "outputs": [],
   "source": [
    "kf = KFold(n_splits = 5, shuffle = True, random_state = 2021)"
   ]
  },
  {
   "cell_type": "code",
   "execution_count": 10,
   "id": "ce689db7-8384-489f-aa15-aa35af1b17bf",
   "metadata": {
    "tags": []
   },
   "outputs": [],
   "source": [
    "model = KerasRegressor(model = build_model, batch_size = 32, validation_split = 0.2, epochs = 20)"
   ]
  },
  {
   "cell_type": "code",
   "execution_count": 11,
   "id": "96b378c7-675d-4278-8eab-1134e2f820f7",
   "metadata": {
    "tags": []
   },
   "outputs": [],
   "source": [
    "grid_search = GridSearchCV(estimator = model, param_grid = param_grid, cv = kf, scoring = 'neg_mean_absolute_error', refit = 'True', verbose = 1)"
   ]
  },
  {
   "cell_type": "code",
   "execution_count": 12,
   "id": "a2d3ff87-3765-4e47-819e-2d04a54f8874",
   "metadata": {
    "tags": []
   },
   "outputs": [
    {
     "name": "stdout",
     "output_type": "stream",
     "text": [
      "Fitting 5 folds for each of 3 candidates, totalling 15 fits\n",
      "Epoch 1/20\n",
      "Epoch 1/20\n",
      "Epoch 1/20\n",
      "Epoch 1/20\n",
      "Epoch 1/20\n",
      "Epoch 1/20\n",
      "Epoch 1/20\n",
      "Epoch 1/20\n",
      "Epoch 1/20\n",
      "Epoch 1/20\n",
      "Epoch 1/20\n",
      "Epoch 1/20\n",
      "Epoch 1/20\n",
      "Epoch 1/20\n",
      "Epoch 1/20\n"
     ]
    },
    {
     "ename": "ValueError",
     "evalue": "\nAll the 15 fits failed.\nIt is very likely that your model is misconfigured.\nYou can try to debug the error by setting error_score='raise'.\n\nBelow are more details about the failures:\n--------------------------------------------------------------------------------\n1 fits failed with the following error:\nTraceback (most recent call last):\n  File \"/home/joana/miniconda3/envs/DAA/lib/python3.10/site-packages/sklearn/model_selection/_validation.py\", line 732, in _fit_and_score\n    estimator.fit(X_train, y_train, **fit_params)\n  File \"/home/joana/miniconda3/envs/DAA/lib/python3.10/site-packages/scikeras/wrappers.py\", line 760, in fit\n    self._fit(\n  File \"/home/joana/miniconda3/envs/DAA/lib/python3.10/site-packages/scikeras/wrappers.py\", line 928, in _fit\n    self._fit_keras_model(\n  File \"/home/joana/miniconda3/envs/DAA/lib/python3.10/site-packages/scikeras/wrappers.py\", line 524, in _fit_keras_model\n    hist = self.model_.fit(x=X, y=y, **fit_args)\n  File \"/home/joana/miniconda3/envs/DAA/lib/python3.10/site-packages/keras/utils/traceback_utils.py\", line 70, in error_handler\n    raise e.with_traceback(filtered_tb) from None\n  File \"/tmp/__autograph_generated_file2s3docdx.py\", line 15, in tf__train_function\n    retval_ = ag__.converted_call(ag__.ld(step_function), (ag__.ld(self), ag__.ld(iterator)), None, fscope)\nValueError: in user code:\n\n    File \"/home/joana/miniconda3/envs/DAA/lib/python3.10/site-packages/keras/engine/training.py\", line 1284, in train_function  *\n        return step_function(self, iterator)\n    File \"/home/joana/miniconda3/envs/DAA/lib/python3.10/site-packages/keras/engine/training.py\", line 1268, in step_function  **\n        outputs = model.distribute_strategy.run(run_step, args=(data,))\n    File \"/home/joana/miniconda3/envs/DAA/lib/python3.10/site-packages/keras/engine/training.py\", line 1249, in run_step  **\n        outputs = model.train_step(data)\n    File \"/home/joana/miniconda3/envs/DAA/lib/python3.10/site-packages/keras/engine/training.py\", line 1050, in train_step\n        y_pred = self(x, training=True)\n    File \"/home/joana/miniconda3/envs/DAA/lib/python3.10/site-packages/keras/utils/traceback_utils.py\", line 70, in error_handler\n        raise e.with_traceback(filtered_tb) from None\n    File \"/home/joana/miniconda3/envs/DAA/lib/python3.10/site-packages/keras/engine/input_spec.py\", line 298, in assert_input_compatibility\n        raise ValueError(\n\n    ValueError: Input 0 of layer \"sequential_1\" is incompatible with the layer: expected shape=(None, 5), found shape=(None, 13)\n\n\n--------------------------------------------------------------------------------\n1 fits failed with the following error:\nTraceback (most recent call last):\n  File \"/home/joana/miniconda3/envs/DAA/lib/python3.10/site-packages/sklearn/model_selection/_validation.py\", line 732, in _fit_and_score\n    estimator.fit(X_train, y_train, **fit_params)\n  File \"/home/joana/miniconda3/envs/DAA/lib/python3.10/site-packages/scikeras/wrappers.py\", line 760, in fit\n    self._fit(\n  File \"/home/joana/miniconda3/envs/DAA/lib/python3.10/site-packages/scikeras/wrappers.py\", line 928, in _fit\n    self._fit_keras_model(\n  File \"/home/joana/miniconda3/envs/DAA/lib/python3.10/site-packages/scikeras/wrappers.py\", line 524, in _fit_keras_model\n    hist = self.model_.fit(x=X, y=y, **fit_args)\n  File \"/home/joana/miniconda3/envs/DAA/lib/python3.10/site-packages/keras/utils/traceback_utils.py\", line 70, in error_handler\n    raise e.with_traceback(filtered_tb) from None\n  File \"/tmp/__autograph_generated_file2s3docdx.py\", line 15, in tf__train_function\n    retval_ = ag__.converted_call(ag__.ld(step_function), (ag__.ld(self), ag__.ld(iterator)), None, fscope)\nValueError: in user code:\n\n    File \"/home/joana/miniconda3/envs/DAA/lib/python3.10/site-packages/keras/engine/training.py\", line 1284, in train_function  *\n        return step_function(self, iterator)\n    File \"/home/joana/miniconda3/envs/DAA/lib/python3.10/site-packages/keras/engine/training.py\", line 1268, in step_function  **\n        outputs = model.distribute_strategy.run(run_step, args=(data,))\n    File \"/home/joana/miniconda3/envs/DAA/lib/python3.10/site-packages/keras/engine/training.py\", line 1249, in run_step  **\n        outputs = model.train_step(data)\n    File \"/home/joana/miniconda3/envs/DAA/lib/python3.10/site-packages/keras/engine/training.py\", line 1050, in train_step\n        y_pred = self(x, training=True)\n    File \"/home/joana/miniconda3/envs/DAA/lib/python3.10/site-packages/keras/utils/traceback_utils.py\", line 70, in error_handler\n        raise e.with_traceback(filtered_tb) from None\n    File \"/home/joana/miniconda3/envs/DAA/lib/python3.10/site-packages/keras/engine/input_spec.py\", line 298, in assert_input_compatibility\n        raise ValueError(\n\n    ValueError: Input 0 of layer \"sequential_2\" is incompatible with the layer: expected shape=(None, 5), found shape=(None, 13)\n\n\n--------------------------------------------------------------------------------\n1 fits failed with the following error:\nTraceback (most recent call last):\n  File \"/home/joana/miniconda3/envs/DAA/lib/python3.10/site-packages/sklearn/model_selection/_validation.py\", line 732, in _fit_and_score\n    estimator.fit(X_train, y_train, **fit_params)\n  File \"/home/joana/miniconda3/envs/DAA/lib/python3.10/site-packages/scikeras/wrappers.py\", line 760, in fit\n    self._fit(\n  File \"/home/joana/miniconda3/envs/DAA/lib/python3.10/site-packages/scikeras/wrappers.py\", line 928, in _fit\n    self._fit_keras_model(\n  File \"/home/joana/miniconda3/envs/DAA/lib/python3.10/site-packages/scikeras/wrappers.py\", line 524, in _fit_keras_model\n    hist = self.model_.fit(x=X, y=y, **fit_args)\n  File \"/home/joana/miniconda3/envs/DAA/lib/python3.10/site-packages/keras/utils/traceback_utils.py\", line 70, in error_handler\n    raise e.with_traceback(filtered_tb) from None\n  File \"/tmp/__autograph_generated_file2s3docdx.py\", line 15, in tf__train_function\n    retval_ = ag__.converted_call(ag__.ld(step_function), (ag__.ld(self), ag__.ld(iterator)), None, fscope)\nValueError: in user code:\n\n    File \"/home/joana/miniconda3/envs/DAA/lib/python3.10/site-packages/keras/engine/training.py\", line 1284, in train_function  *\n        return step_function(self, iterator)\n    File \"/home/joana/miniconda3/envs/DAA/lib/python3.10/site-packages/keras/engine/training.py\", line 1268, in step_function  **\n        outputs = model.distribute_strategy.run(run_step, args=(data,))\n    File \"/home/joana/miniconda3/envs/DAA/lib/python3.10/site-packages/keras/engine/training.py\", line 1249, in run_step  **\n        outputs = model.train_step(data)\n    File \"/home/joana/miniconda3/envs/DAA/lib/python3.10/site-packages/keras/engine/training.py\", line 1050, in train_step\n        y_pred = self(x, training=True)\n    File \"/home/joana/miniconda3/envs/DAA/lib/python3.10/site-packages/keras/utils/traceback_utils.py\", line 70, in error_handler\n        raise e.with_traceback(filtered_tb) from None\n    File \"/home/joana/miniconda3/envs/DAA/lib/python3.10/site-packages/keras/engine/input_spec.py\", line 298, in assert_input_compatibility\n        raise ValueError(\n\n    ValueError: Input 0 of layer \"sequential_3\" is incompatible with the layer: expected shape=(None, 5), found shape=(None, 13)\n\n\n--------------------------------------------------------------------------------\n1 fits failed with the following error:\nTraceback (most recent call last):\n  File \"/home/joana/miniconda3/envs/DAA/lib/python3.10/site-packages/sklearn/model_selection/_validation.py\", line 732, in _fit_and_score\n    estimator.fit(X_train, y_train, **fit_params)\n  File \"/home/joana/miniconda3/envs/DAA/lib/python3.10/site-packages/scikeras/wrappers.py\", line 760, in fit\n    self._fit(\n  File \"/home/joana/miniconda3/envs/DAA/lib/python3.10/site-packages/scikeras/wrappers.py\", line 928, in _fit\n    self._fit_keras_model(\n  File \"/home/joana/miniconda3/envs/DAA/lib/python3.10/site-packages/scikeras/wrappers.py\", line 524, in _fit_keras_model\n    hist = self.model_.fit(x=X, y=y, **fit_args)\n  File \"/home/joana/miniconda3/envs/DAA/lib/python3.10/site-packages/keras/utils/traceback_utils.py\", line 70, in error_handler\n    raise e.with_traceback(filtered_tb) from None\n  File \"/tmp/__autograph_generated_file2s3docdx.py\", line 15, in tf__train_function\n    retval_ = ag__.converted_call(ag__.ld(step_function), (ag__.ld(self), ag__.ld(iterator)), None, fscope)\nValueError: in user code:\n\n    File \"/home/joana/miniconda3/envs/DAA/lib/python3.10/site-packages/keras/engine/training.py\", line 1284, in train_function  *\n        return step_function(self, iterator)\n    File \"/home/joana/miniconda3/envs/DAA/lib/python3.10/site-packages/keras/engine/training.py\", line 1268, in step_function  **\n        outputs = model.distribute_strategy.run(run_step, args=(data,))\n    File \"/home/joana/miniconda3/envs/DAA/lib/python3.10/site-packages/keras/engine/training.py\", line 1249, in run_step  **\n        outputs = model.train_step(data)\n    File \"/home/joana/miniconda3/envs/DAA/lib/python3.10/site-packages/keras/engine/training.py\", line 1050, in train_step\n        y_pred = self(x, training=True)\n    File \"/home/joana/miniconda3/envs/DAA/lib/python3.10/site-packages/keras/utils/traceback_utils.py\", line 70, in error_handler\n        raise e.with_traceback(filtered_tb) from None\n    File \"/home/joana/miniconda3/envs/DAA/lib/python3.10/site-packages/keras/engine/input_spec.py\", line 298, in assert_input_compatibility\n        raise ValueError(\n\n    ValueError: Input 0 of layer \"sequential_4\" is incompatible with the layer: expected shape=(None, 5), found shape=(None, 13)\n\n\n--------------------------------------------------------------------------------\n1 fits failed with the following error:\nTraceback (most recent call last):\n  File \"/home/joana/miniconda3/envs/DAA/lib/python3.10/site-packages/sklearn/model_selection/_validation.py\", line 732, in _fit_and_score\n    estimator.fit(X_train, y_train, **fit_params)\n  File \"/home/joana/miniconda3/envs/DAA/lib/python3.10/site-packages/scikeras/wrappers.py\", line 760, in fit\n    self._fit(\n  File \"/home/joana/miniconda3/envs/DAA/lib/python3.10/site-packages/scikeras/wrappers.py\", line 928, in _fit\n    self._fit_keras_model(\n  File \"/home/joana/miniconda3/envs/DAA/lib/python3.10/site-packages/scikeras/wrappers.py\", line 524, in _fit_keras_model\n    hist = self.model_.fit(x=X, y=y, **fit_args)\n  File \"/home/joana/miniconda3/envs/DAA/lib/python3.10/site-packages/keras/utils/traceback_utils.py\", line 70, in error_handler\n    raise e.with_traceback(filtered_tb) from None\n  File \"/tmp/__autograph_generated_file2s3docdx.py\", line 15, in tf__train_function\n    retval_ = ag__.converted_call(ag__.ld(step_function), (ag__.ld(self), ag__.ld(iterator)), None, fscope)\nValueError: in user code:\n\n    File \"/home/joana/miniconda3/envs/DAA/lib/python3.10/site-packages/keras/engine/training.py\", line 1284, in train_function  *\n        return step_function(self, iterator)\n    File \"/home/joana/miniconda3/envs/DAA/lib/python3.10/site-packages/keras/engine/training.py\", line 1268, in step_function  **\n        outputs = model.distribute_strategy.run(run_step, args=(data,))\n    File \"/home/joana/miniconda3/envs/DAA/lib/python3.10/site-packages/keras/engine/training.py\", line 1249, in run_step  **\n        outputs = model.train_step(data)\n    File \"/home/joana/miniconda3/envs/DAA/lib/python3.10/site-packages/keras/engine/training.py\", line 1050, in train_step\n        y_pred = self(x, training=True)\n    File \"/home/joana/miniconda3/envs/DAA/lib/python3.10/site-packages/keras/utils/traceback_utils.py\", line 70, in error_handler\n        raise e.with_traceback(filtered_tb) from None\n    File \"/home/joana/miniconda3/envs/DAA/lib/python3.10/site-packages/keras/engine/input_spec.py\", line 298, in assert_input_compatibility\n        raise ValueError(\n\n    ValueError: Input 0 of layer \"sequential_5\" is incompatible with the layer: expected shape=(None, 5), found shape=(None, 13)\n\n\n--------------------------------------------------------------------------------\n1 fits failed with the following error:\nTraceback (most recent call last):\n  File \"/home/joana/miniconda3/envs/DAA/lib/python3.10/site-packages/sklearn/model_selection/_validation.py\", line 732, in _fit_and_score\n    estimator.fit(X_train, y_train, **fit_params)\n  File \"/home/joana/miniconda3/envs/DAA/lib/python3.10/site-packages/scikeras/wrappers.py\", line 760, in fit\n    self._fit(\n  File \"/home/joana/miniconda3/envs/DAA/lib/python3.10/site-packages/scikeras/wrappers.py\", line 928, in _fit\n    self._fit_keras_model(\n  File \"/home/joana/miniconda3/envs/DAA/lib/python3.10/site-packages/scikeras/wrappers.py\", line 524, in _fit_keras_model\n    hist = self.model_.fit(x=X, y=y, **fit_args)\n  File \"/home/joana/miniconda3/envs/DAA/lib/python3.10/site-packages/keras/utils/traceback_utils.py\", line 70, in error_handler\n    raise e.with_traceback(filtered_tb) from None\n  File \"/tmp/__autograph_generated_file2s3docdx.py\", line 15, in tf__train_function\n    retval_ = ag__.converted_call(ag__.ld(step_function), (ag__.ld(self), ag__.ld(iterator)), None, fscope)\nValueError: in user code:\n\n    File \"/home/joana/miniconda3/envs/DAA/lib/python3.10/site-packages/keras/engine/training.py\", line 1284, in train_function  *\n        return step_function(self, iterator)\n    File \"/home/joana/miniconda3/envs/DAA/lib/python3.10/site-packages/keras/engine/training.py\", line 1268, in step_function  **\n        outputs = model.distribute_strategy.run(run_step, args=(data,))\n    File \"/home/joana/miniconda3/envs/DAA/lib/python3.10/site-packages/keras/engine/training.py\", line 1249, in run_step  **\n        outputs = model.train_step(data)\n    File \"/home/joana/miniconda3/envs/DAA/lib/python3.10/site-packages/keras/engine/training.py\", line 1050, in train_step\n        y_pred = self(x, training=True)\n    File \"/home/joana/miniconda3/envs/DAA/lib/python3.10/site-packages/keras/utils/traceback_utils.py\", line 70, in error_handler\n        raise e.with_traceback(filtered_tb) from None\n    File \"/home/joana/miniconda3/envs/DAA/lib/python3.10/site-packages/keras/engine/input_spec.py\", line 298, in assert_input_compatibility\n        raise ValueError(\n\n    ValueError: Input 0 of layer \"sequential_6\" is incompatible with the layer: expected shape=(None, 5), found shape=(None, 13)\n\n\n--------------------------------------------------------------------------------\n1 fits failed with the following error:\nTraceback (most recent call last):\n  File \"/home/joana/miniconda3/envs/DAA/lib/python3.10/site-packages/sklearn/model_selection/_validation.py\", line 732, in _fit_and_score\n    estimator.fit(X_train, y_train, **fit_params)\n  File \"/home/joana/miniconda3/envs/DAA/lib/python3.10/site-packages/scikeras/wrappers.py\", line 760, in fit\n    self._fit(\n  File \"/home/joana/miniconda3/envs/DAA/lib/python3.10/site-packages/scikeras/wrappers.py\", line 928, in _fit\n    self._fit_keras_model(\n  File \"/home/joana/miniconda3/envs/DAA/lib/python3.10/site-packages/scikeras/wrappers.py\", line 524, in _fit_keras_model\n    hist = self.model_.fit(x=X, y=y, **fit_args)\n  File \"/home/joana/miniconda3/envs/DAA/lib/python3.10/site-packages/keras/utils/traceback_utils.py\", line 70, in error_handler\n    raise e.with_traceback(filtered_tb) from None\n  File \"/tmp/__autograph_generated_file2s3docdx.py\", line 15, in tf__train_function\n    retval_ = ag__.converted_call(ag__.ld(step_function), (ag__.ld(self), ag__.ld(iterator)), None, fscope)\nValueError: in user code:\n\n    File \"/home/joana/miniconda3/envs/DAA/lib/python3.10/site-packages/keras/engine/training.py\", line 1284, in train_function  *\n        return step_function(self, iterator)\n    File \"/home/joana/miniconda3/envs/DAA/lib/python3.10/site-packages/keras/engine/training.py\", line 1268, in step_function  **\n        outputs = model.distribute_strategy.run(run_step, args=(data,))\n    File \"/home/joana/miniconda3/envs/DAA/lib/python3.10/site-packages/keras/engine/training.py\", line 1249, in run_step  **\n        outputs = model.train_step(data)\n    File \"/home/joana/miniconda3/envs/DAA/lib/python3.10/site-packages/keras/engine/training.py\", line 1050, in train_step\n        y_pred = self(x, training=True)\n    File \"/home/joana/miniconda3/envs/DAA/lib/python3.10/site-packages/keras/utils/traceback_utils.py\", line 70, in error_handler\n        raise e.with_traceback(filtered_tb) from None\n    File \"/home/joana/miniconda3/envs/DAA/lib/python3.10/site-packages/keras/engine/input_spec.py\", line 298, in assert_input_compatibility\n        raise ValueError(\n\n    ValueError: Input 0 of layer \"sequential_7\" is incompatible with the layer: expected shape=(None, 5), found shape=(None, 13)\n\n\n--------------------------------------------------------------------------------\n1 fits failed with the following error:\nTraceback (most recent call last):\n  File \"/home/joana/miniconda3/envs/DAA/lib/python3.10/site-packages/sklearn/model_selection/_validation.py\", line 732, in _fit_and_score\n    estimator.fit(X_train, y_train, **fit_params)\n  File \"/home/joana/miniconda3/envs/DAA/lib/python3.10/site-packages/scikeras/wrappers.py\", line 760, in fit\n    self._fit(\n  File \"/home/joana/miniconda3/envs/DAA/lib/python3.10/site-packages/scikeras/wrappers.py\", line 928, in _fit\n    self._fit_keras_model(\n  File \"/home/joana/miniconda3/envs/DAA/lib/python3.10/site-packages/scikeras/wrappers.py\", line 524, in _fit_keras_model\n    hist = self.model_.fit(x=X, y=y, **fit_args)\n  File \"/home/joana/miniconda3/envs/DAA/lib/python3.10/site-packages/keras/utils/traceback_utils.py\", line 70, in error_handler\n    raise e.with_traceback(filtered_tb) from None\n  File \"/tmp/__autograph_generated_file2s3docdx.py\", line 15, in tf__train_function\n    retval_ = ag__.converted_call(ag__.ld(step_function), (ag__.ld(self), ag__.ld(iterator)), None, fscope)\nValueError: in user code:\n\n    File \"/home/joana/miniconda3/envs/DAA/lib/python3.10/site-packages/keras/engine/training.py\", line 1284, in train_function  *\n        return step_function(self, iterator)\n    File \"/home/joana/miniconda3/envs/DAA/lib/python3.10/site-packages/keras/engine/training.py\", line 1268, in step_function  **\n        outputs = model.distribute_strategy.run(run_step, args=(data,))\n    File \"/home/joana/miniconda3/envs/DAA/lib/python3.10/site-packages/keras/engine/training.py\", line 1249, in run_step  **\n        outputs = model.train_step(data)\n    File \"/home/joana/miniconda3/envs/DAA/lib/python3.10/site-packages/keras/engine/training.py\", line 1050, in train_step\n        y_pred = self(x, training=True)\n    File \"/home/joana/miniconda3/envs/DAA/lib/python3.10/site-packages/keras/utils/traceback_utils.py\", line 70, in error_handler\n        raise e.with_traceback(filtered_tb) from None\n    File \"/home/joana/miniconda3/envs/DAA/lib/python3.10/site-packages/keras/engine/input_spec.py\", line 298, in assert_input_compatibility\n        raise ValueError(\n\n    ValueError: Input 0 of layer \"sequential_8\" is incompatible with the layer: expected shape=(None, 5), found shape=(None, 13)\n\n\n--------------------------------------------------------------------------------\n1 fits failed with the following error:\nTraceback (most recent call last):\n  File \"/home/joana/miniconda3/envs/DAA/lib/python3.10/site-packages/sklearn/model_selection/_validation.py\", line 732, in _fit_and_score\n    estimator.fit(X_train, y_train, **fit_params)\n  File \"/home/joana/miniconda3/envs/DAA/lib/python3.10/site-packages/scikeras/wrappers.py\", line 760, in fit\n    self._fit(\n  File \"/home/joana/miniconda3/envs/DAA/lib/python3.10/site-packages/scikeras/wrappers.py\", line 928, in _fit\n    self._fit_keras_model(\n  File \"/home/joana/miniconda3/envs/DAA/lib/python3.10/site-packages/scikeras/wrappers.py\", line 524, in _fit_keras_model\n    hist = self.model_.fit(x=X, y=y, **fit_args)\n  File \"/home/joana/miniconda3/envs/DAA/lib/python3.10/site-packages/keras/utils/traceback_utils.py\", line 70, in error_handler\n    raise e.with_traceback(filtered_tb) from None\n  File \"/tmp/__autograph_generated_file2s3docdx.py\", line 15, in tf__train_function\n    retval_ = ag__.converted_call(ag__.ld(step_function), (ag__.ld(self), ag__.ld(iterator)), None, fscope)\nValueError: in user code:\n\n    File \"/home/joana/miniconda3/envs/DAA/lib/python3.10/site-packages/keras/engine/training.py\", line 1284, in train_function  *\n        return step_function(self, iterator)\n    File \"/home/joana/miniconda3/envs/DAA/lib/python3.10/site-packages/keras/engine/training.py\", line 1268, in step_function  **\n        outputs = model.distribute_strategy.run(run_step, args=(data,))\n    File \"/home/joana/miniconda3/envs/DAA/lib/python3.10/site-packages/keras/engine/training.py\", line 1249, in run_step  **\n        outputs = model.train_step(data)\n    File \"/home/joana/miniconda3/envs/DAA/lib/python3.10/site-packages/keras/engine/training.py\", line 1050, in train_step\n        y_pred = self(x, training=True)\n    File \"/home/joana/miniconda3/envs/DAA/lib/python3.10/site-packages/keras/utils/traceback_utils.py\", line 70, in error_handler\n        raise e.with_traceback(filtered_tb) from None\n    File \"/home/joana/miniconda3/envs/DAA/lib/python3.10/site-packages/keras/engine/input_spec.py\", line 298, in assert_input_compatibility\n        raise ValueError(\n\n    ValueError: Input 0 of layer \"sequential_9\" is incompatible with the layer: expected shape=(None, 5), found shape=(None, 13)\n\n\n--------------------------------------------------------------------------------\n1 fits failed with the following error:\nTraceback (most recent call last):\n  File \"/home/joana/miniconda3/envs/DAA/lib/python3.10/site-packages/sklearn/model_selection/_validation.py\", line 732, in _fit_and_score\n    estimator.fit(X_train, y_train, **fit_params)\n  File \"/home/joana/miniconda3/envs/DAA/lib/python3.10/site-packages/scikeras/wrappers.py\", line 760, in fit\n    self._fit(\n  File \"/home/joana/miniconda3/envs/DAA/lib/python3.10/site-packages/scikeras/wrappers.py\", line 928, in _fit\n    self._fit_keras_model(\n  File \"/home/joana/miniconda3/envs/DAA/lib/python3.10/site-packages/scikeras/wrappers.py\", line 524, in _fit_keras_model\n    hist = self.model_.fit(x=X, y=y, **fit_args)\n  File \"/home/joana/miniconda3/envs/DAA/lib/python3.10/site-packages/keras/utils/traceback_utils.py\", line 70, in error_handler\n    raise e.with_traceback(filtered_tb) from None\n  File \"/tmp/__autograph_generated_file2s3docdx.py\", line 15, in tf__train_function\n    retval_ = ag__.converted_call(ag__.ld(step_function), (ag__.ld(self), ag__.ld(iterator)), None, fscope)\nValueError: in user code:\n\n    File \"/home/joana/miniconda3/envs/DAA/lib/python3.10/site-packages/keras/engine/training.py\", line 1284, in train_function  *\n        return step_function(self, iterator)\n    File \"/home/joana/miniconda3/envs/DAA/lib/python3.10/site-packages/keras/engine/training.py\", line 1268, in step_function  **\n        outputs = model.distribute_strategy.run(run_step, args=(data,))\n    File \"/home/joana/miniconda3/envs/DAA/lib/python3.10/site-packages/keras/engine/training.py\", line 1249, in run_step  **\n        outputs = model.train_step(data)\n    File \"/home/joana/miniconda3/envs/DAA/lib/python3.10/site-packages/keras/engine/training.py\", line 1050, in train_step\n        y_pred = self(x, training=True)\n    File \"/home/joana/miniconda3/envs/DAA/lib/python3.10/site-packages/keras/utils/traceback_utils.py\", line 70, in error_handler\n        raise e.with_traceback(filtered_tb) from None\n    File \"/home/joana/miniconda3/envs/DAA/lib/python3.10/site-packages/keras/engine/input_spec.py\", line 298, in assert_input_compatibility\n        raise ValueError(\n\n    ValueError: Input 0 of layer \"sequential_10\" is incompatible with the layer: expected shape=(None, 5), found shape=(None, 13)\n\n\n--------------------------------------------------------------------------------\n1 fits failed with the following error:\nTraceback (most recent call last):\n  File \"/home/joana/miniconda3/envs/DAA/lib/python3.10/site-packages/sklearn/model_selection/_validation.py\", line 732, in _fit_and_score\n    estimator.fit(X_train, y_train, **fit_params)\n  File \"/home/joana/miniconda3/envs/DAA/lib/python3.10/site-packages/scikeras/wrappers.py\", line 760, in fit\n    self._fit(\n  File \"/home/joana/miniconda3/envs/DAA/lib/python3.10/site-packages/scikeras/wrappers.py\", line 928, in _fit\n    self._fit_keras_model(\n  File \"/home/joana/miniconda3/envs/DAA/lib/python3.10/site-packages/scikeras/wrappers.py\", line 524, in _fit_keras_model\n    hist = self.model_.fit(x=X, y=y, **fit_args)\n  File \"/home/joana/miniconda3/envs/DAA/lib/python3.10/site-packages/keras/utils/traceback_utils.py\", line 70, in error_handler\n    raise e.with_traceback(filtered_tb) from None\n  File \"/tmp/__autograph_generated_file2s3docdx.py\", line 15, in tf__train_function\n    retval_ = ag__.converted_call(ag__.ld(step_function), (ag__.ld(self), ag__.ld(iterator)), None, fscope)\nValueError: in user code:\n\n    File \"/home/joana/miniconda3/envs/DAA/lib/python3.10/site-packages/keras/engine/training.py\", line 1284, in train_function  *\n        return step_function(self, iterator)\n    File \"/home/joana/miniconda3/envs/DAA/lib/python3.10/site-packages/keras/engine/training.py\", line 1268, in step_function  **\n        outputs = model.distribute_strategy.run(run_step, args=(data,))\n    File \"/home/joana/miniconda3/envs/DAA/lib/python3.10/site-packages/keras/engine/training.py\", line 1249, in run_step  **\n        outputs = model.train_step(data)\n    File \"/home/joana/miniconda3/envs/DAA/lib/python3.10/site-packages/keras/engine/training.py\", line 1050, in train_step\n        y_pred = self(x, training=True)\n    File \"/home/joana/miniconda3/envs/DAA/lib/python3.10/site-packages/keras/utils/traceback_utils.py\", line 70, in error_handler\n        raise e.with_traceback(filtered_tb) from None\n    File \"/home/joana/miniconda3/envs/DAA/lib/python3.10/site-packages/keras/engine/input_spec.py\", line 298, in assert_input_compatibility\n        raise ValueError(\n\n    ValueError: Input 0 of layer \"sequential_11\" is incompatible with the layer: expected shape=(None, 5), found shape=(None, 13)\n\n\n--------------------------------------------------------------------------------\n1 fits failed with the following error:\nTraceback (most recent call last):\n  File \"/home/joana/miniconda3/envs/DAA/lib/python3.10/site-packages/sklearn/model_selection/_validation.py\", line 732, in _fit_and_score\n    estimator.fit(X_train, y_train, **fit_params)\n  File \"/home/joana/miniconda3/envs/DAA/lib/python3.10/site-packages/scikeras/wrappers.py\", line 760, in fit\n    self._fit(\n  File \"/home/joana/miniconda3/envs/DAA/lib/python3.10/site-packages/scikeras/wrappers.py\", line 928, in _fit\n    self._fit_keras_model(\n  File \"/home/joana/miniconda3/envs/DAA/lib/python3.10/site-packages/scikeras/wrappers.py\", line 524, in _fit_keras_model\n    hist = self.model_.fit(x=X, y=y, **fit_args)\n  File \"/home/joana/miniconda3/envs/DAA/lib/python3.10/site-packages/keras/utils/traceback_utils.py\", line 70, in error_handler\n    raise e.with_traceback(filtered_tb) from None\n  File \"/tmp/__autograph_generated_file2s3docdx.py\", line 15, in tf__train_function\n    retval_ = ag__.converted_call(ag__.ld(step_function), (ag__.ld(self), ag__.ld(iterator)), None, fscope)\nValueError: in user code:\n\n    File \"/home/joana/miniconda3/envs/DAA/lib/python3.10/site-packages/keras/engine/training.py\", line 1284, in train_function  *\n        return step_function(self, iterator)\n    File \"/home/joana/miniconda3/envs/DAA/lib/python3.10/site-packages/keras/engine/training.py\", line 1268, in step_function  **\n        outputs = model.distribute_strategy.run(run_step, args=(data,))\n    File \"/home/joana/miniconda3/envs/DAA/lib/python3.10/site-packages/keras/engine/training.py\", line 1249, in run_step  **\n        outputs = model.train_step(data)\n    File \"/home/joana/miniconda3/envs/DAA/lib/python3.10/site-packages/keras/engine/training.py\", line 1050, in train_step\n        y_pred = self(x, training=True)\n    File \"/home/joana/miniconda3/envs/DAA/lib/python3.10/site-packages/keras/utils/traceback_utils.py\", line 70, in error_handler\n        raise e.with_traceback(filtered_tb) from None\n    File \"/home/joana/miniconda3/envs/DAA/lib/python3.10/site-packages/keras/engine/input_spec.py\", line 298, in assert_input_compatibility\n        raise ValueError(\n\n    ValueError: Input 0 of layer \"sequential_12\" is incompatible with the layer: expected shape=(None, 5), found shape=(None, 13)\n\n\n--------------------------------------------------------------------------------\n1 fits failed with the following error:\nTraceback (most recent call last):\n  File \"/home/joana/miniconda3/envs/DAA/lib/python3.10/site-packages/sklearn/model_selection/_validation.py\", line 732, in _fit_and_score\n    estimator.fit(X_train, y_train, **fit_params)\n  File \"/home/joana/miniconda3/envs/DAA/lib/python3.10/site-packages/scikeras/wrappers.py\", line 760, in fit\n    self._fit(\n  File \"/home/joana/miniconda3/envs/DAA/lib/python3.10/site-packages/scikeras/wrappers.py\", line 928, in _fit\n    self._fit_keras_model(\n  File \"/home/joana/miniconda3/envs/DAA/lib/python3.10/site-packages/scikeras/wrappers.py\", line 524, in _fit_keras_model\n    hist = self.model_.fit(x=X, y=y, **fit_args)\n  File \"/home/joana/miniconda3/envs/DAA/lib/python3.10/site-packages/keras/utils/traceback_utils.py\", line 70, in error_handler\n    raise e.with_traceback(filtered_tb) from None\n  File \"/tmp/__autograph_generated_file2s3docdx.py\", line 15, in tf__train_function\n    retval_ = ag__.converted_call(ag__.ld(step_function), (ag__.ld(self), ag__.ld(iterator)), None, fscope)\nValueError: in user code:\n\n    File \"/home/joana/miniconda3/envs/DAA/lib/python3.10/site-packages/keras/engine/training.py\", line 1284, in train_function  *\n        return step_function(self, iterator)\n    File \"/home/joana/miniconda3/envs/DAA/lib/python3.10/site-packages/keras/engine/training.py\", line 1268, in step_function  **\n        outputs = model.distribute_strategy.run(run_step, args=(data,))\n    File \"/home/joana/miniconda3/envs/DAA/lib/python3.10/site-packages/keras/engine/training.py\", line 1249, in run_step  **\n        outputs = model.train_step(data)\n    File \"/home/joana/miniconda3/envs/DAA/lib/python3.10/site-packages/keras/engine/training.py\", line 1050, in train_step\n        y_pred = self(x, training=True)\n    File \"/home/joana/miniconda3/envs/DAA/lib/python3.10/site-packages/keras/utils/traceback_utils.py\", line 70, in error_handler\n        raise e.with_traceback(filtered_tb) from None\n    File \"/home/joana/miniconda3/envs/DAA/lib/python3.10/site-packages/keras/engine/input_spec.py\", line 298, in assert_input_compatibility\n        raise ValueError(\n\n    ValueError: Input 0 of layer \"sequential_13\" is incompatible with the layer: expected shape=(None, 5), found shape=(None, 13)\n\n\n--------------------------------------------------------------------------------\n1 fits failed with the following error:\nTraceback (most recent call last):\n  File \"/home/joana/miniconda3/envs/DAA/lib/python3.10/site-packages/sklearn/model_selection/_validation.py\", line 732, in _fit_and_score\n    estimator.fit(X_train, y_train, **fit_params)\n  File \"/home/joana/miniconda3/envs/DAA/lib/python3.10/site-packages/scikeras/wrappers.py\", line 760, in fit\n    self._fit(\n  File \"/home/joana/miniconda3/envs/DAA/lib/python3.10/site-packages/scikeras/wrappers.py\", line 928, in _fit\n    self._fit_keras_model(\n  File \"/home/joana/miniconda3/envs/DAA/lib/python3.10/site-packages/scikeras/wrappers.py\", line 524, in _fit_keras_model\n    hist = self.model_.fit(x=X, y=y, **fit_args)\n  File \"/home/joana/miniconda3/envs/DAA/lib/python3.10/site-packages/keras/utils/traceback_utils.py\", line 70, in error_handler\n    raise e.with_traceback(filtered_tb) from None\n  File \"/tmp/__autograph_generated_file2s3docdx.py\", line 15, in tf__train_function\n    retval_ = ag__.converted_call(ag__.ld(step_function), (ag__.ld(self), ag__.ld(iterator)), None, fscope)\nValueError: in user code:\n\n    File \"/home/joana/miniconda3/envs/DAA/lib/python3.10/site-packages/keras/engine/training.py\", line 1284, in train_function  *\n        return step_function(self, iterator)\n    File \"/home/joana/miniconda3/envs/DAA/lib/python3.10/site-packages/keras/engine/training.py\", line 1268, in step_function  **\n        outputs = model.distribute_strategy.run(run_step, args=(data,))\n    File \"/home/joana/miniconda3/envs/DAA/lib/python3.10/site-packages/keras/engine/training.py\", line 1249, in run_step  **\n        outputs = model.train_step(data)\n    File \"/home/joana/miniconda3/envs/DAA/lib/python3.10/site-packages/keras/engine/training.py\", line 1050, in train_step\n        y_pred = self(x, training=True)\n    File \"/home/joana/miniconda3/envs/DAA/lib/python3.10/site-packages/keras/utils/traceback_utils.py\", line 70, in error_handler\n        raise e.with_traceback(filtered_tb) from None\n    File \"/home/joana/miniconda3/envs/DAA/lib/python3.10/site-packages/keras/engine/input_spec.py\", line 298, in assert_input_compatibility\n        raise ValueError(\n\n    ValueError: Input 0 of layer \"sequential_14\" is incompatible with the layer: expected shape=(None, 5), found shape=(None, 13)\n\n\n--------------------------------------------------------------------------------\n1 fits failed with the following error:\nTraceback (most recent call last):\n  File \"/home/joana/miniconda3/envs/DAA/lib/python3.10/site-packages/sklearn/model_selection/_validation.py\", line 732, in _fit_and_score\n    estimator.fit(X_train, y_train, **fit_params)\n  File \"/home/joana/miniconda3/envs/DAA/lib/python3.10/site-packages/scikeras/wrappers.py\", line 760, in fit\n    self._fit(\n  File \"/home/joana/miniconda3/envs/DAA/lib/python3.10/site-packages/scikeras/wrappers.py\", line 928, in _fit\n    self._fit_keras_model(\n  File \"/home/joana/miniconda3/envs/DAA/lib/python3.10/site-packages/scikeras/wrappers.py\", line 524, in _fit_keras_model\n    hist = self.model_.fit(x=X, y=y, **fit_args)\n  File \"/home/joana/miniconda3/envs/DAA/lib/python3.10/site-packages/keras/utils/traceback_utils.py\", line 70, in error_handler\n    raise e.with_traceback(filtered_tb) from None\n  File \"/tmp/__autograph_generated_file2s3docdx.py\", line 15, in tf__train_function\n    retval_ = ag__.converted_call(ag__.ld(step_function), (ag__.ld(self), ag__.ld(iterator)), None, fscope)\nValueError: in user code:\n\n    File \"/home/joana/miniconda3/envs/DAA/lib/python3.10/site-packages/keras/engine/training.py\", line 1284, in train_function  *\n        return step_function(self, iterator)\n    File \"/home/joana/miniconda3/envs/DAA/lib/python3.10/site-packages/keras/engine/training.py\", line 1268, in step_function  **\n        outputs = model.distribute_strategy.run(run_step, args=(data,))\n    File \"/home/joana/miniconda3/envs/DAA/lib/python3.10/site-packages/keras/engine/training.py\", line 1249, in run_step  **\n        outputs = model.train_step(data)\n    File \"/home/joana/miniconda3/envs/DAA/lib/python3.10/site-packages/keras/engine/training.py\", line 1050, in train_step\n        y_pred = self(x, training=True)\n    File \"/home/joana/miniconda3/envs/DAA/lib/python3.10/site-packages/keras/utils/traceback_utils.py\", line 70, in error_handler\n        raise e.with_traceback(filtered_tb) from None\n    File \"/home/joana/miniconda3/envs/DAA/lib/python3.10/site-packages/keras/engine/input_spec.py\", line 298, in assert_input_compatibility\n        raise ValueError(\n\n    ValueError: Input 0 of layer \"sequential_15\" is incompatible with the layer: expected shape=(None, 5), found shape=(None, 13)\n\n",
     "output_type": "error",
     "traceback": [
      "\u001b[0;31m---------------------------------------------------------------------------\u001b[0m",
      "\u001b[0;31mValueError\u001b[0m                                Traceback (most recent call last)",
      "Cell \u001b[0;32mIn[12], line 1\u001b[0m\n\u001b[0;32m----> 1\u001b[0m \u001b[43mgrid_search\u001b[49m\u001b[38;5;241;43m.\u001b[39;49m\u001b[43mfit\u001b[49m\u001b[43m(\u001b[49m\u001b[43mX_train\u001b[49m\u001b[43m,\u001b[49m\u001b[43m \u001b[49m\u001b[43my_train\u001b[49m\u001b[43m)\u001b[49m\n",
      "File \u001b[0;32m~/miniconda3/envs/DAA/lib/python3.10/site-packages/sklearn/base.py:1151\u001b[0m, in \u001b[0;36m_fit_context.<locals>.decorator.<locals>.wrapper\u001b[0;34m(estimator, *args, **kwargs)\u001b[0m\n\u001b[1;32m   1144\u001b[0m     estimator\u001b[38;5;241m.\u001b[39m_validate_params()\n\u001b[1;32m   1146\u001b[0m \u001b[38;5;28;01mwith\u001b[39;00m config_context(\n\u001b[1;32m   1147\u001b[0m     skip_parameter_validation\u001b[38;5;241m=\u001b[39m(\n\u001b[1;32m   1148\u001b[0m         prefer_skip_nested_validation \u001b[38;5;129;01mor\u001b[39;00m global_skip_validation\n\u001b[1;32m   1149\u001b[0m     )\n\u001b[1;32m   1150\u001b[0m ):\n\u001b[0;32m-> 1151\u001b[0m     \u001b[38;5;28;01mreturn\u001b[39;00m \u001b[43mfit_method\u001b[49m\u001b[43m(\u001b[49m\u001b[43mestimator\u001b[49m\u001b[43m,\u001b[49m\u001b[43m \u001b[49m\u001b[38;5;241;43m*\u001b[39;49m\u001b[43margs\u001b[49m\u001b[43m,\u001b[49m\u001b[43m \u001b[49m\u001b[38;5;241;43m*\u001b[39;49m\u001b[38;5;241;43m*\u001b[39;49m\u001b[43mkwargs\u001b[49m\u001b[43m)\u001b[49m\n",
      "File \u001b[0;32m~/miniconda3/envs/DAA/lib/python3.10/site-packages/sklearn/model_selection/_search.py:898\u001b[0m, in \u001b[0;36mBaseSearchCV.fit\u001b[0;34m(self, X, y, groups, **fit_params)\u001b[0m\n\u001b[1;32m    892\u001b[0m     results \u001b[38;5;241m=\u001b[39m \u001b[38;5;28mself\u001b[39m\u001b[38;5;241m.\u001b[39m_format_results(\n\u001b[1;32m    893\u001b[0m         all_candidate_params, n_splits, all_out, all_more_results\n\u001b[1;32m    894\u001b[0m     )\n\u001b[1;32m    896\u001b[0m     \u001b[38;5;28;01mreturn\u001b[39;00m results\n\u001b[0;32m--> 898\u001b[0m \u001b[38;5;28;43mself\u001b[39;49m\u001b[38;5;241;43m.\u001b[39;49m\u001b[43m_run_search\u001b[49m\u001b[43m(\u001b[49m\u001b[43mevaluate_candidates\u001b[49m\u001b[43m)\u001b[49m\n\u001b[1;32m    900\u001b[0m \u001b[38;5;66;03m# multimetric is determined here because in the case of a callable\u001b[39;00m\n\u001b[1;32m    901\u001b[0m \u001b[38;5;66;03m# self.scoring the return type is only known after calling\u001b[39;00m\n\u001b[1;32m    902\u001b[0m first_test_score \u001b[38;5;241m=\u001b[39m all_out[\u001b[38;5;241m0\u001b[39m][\u001b[38;5;124m\"\u001b[39m\u001b[38;5;124mtest_scores\u001b[39m\u001b[38;5;124m\"\u001b[39m]\n",
      "File \u001b[0;32m~/miniconda3/envs/DAA/lib/python3.10/site-packages/sklearn/model_selection/_search.py:1419\u001b[0m, in \u001b[0;36mGridSearchCV._run_search\u001b[0;34m(self, evaluate_candidates)\u001b[0m\n\u001b[1;32m   1417\u001b[0m \u001b[38;5;28;01mdef\u001b[39;00m \u001b[38;5;21m_run_search\u001b[39m(\u001b[38;5;28mself\u001b[39m, evaluate_candidates):\n\u001b[1;32m   1418\u001b[0m \u001b[38;5;250m    \u001b[39m\u001b[38;5;124;03m\"\"\"Search all candidates in param_grid\"\"\"\u001b[39;00m\n\u001b[0;32m-> 1419\u001b[0m     \u001b[43mevaluate_candidates\u001b[49m\u001b[43m(\u001b[49m\u001b[43mParameterGrid\u001b[49m\u001b[43m(\u001b[49m\u001b[38;5;28;43mself\u001b[39;49m\u001b[38;5;241;43m.\u001b[39;49m\u001b[43mparam_grid\u001b[49m\u001b[43m)\u001b[49m\u001b[43m)\u001b[49m\n",
      "File \u001b[0;32m~/miniconda3/envs/DAA/lib/python3.10/site-packages/sklearn/model_selection/_search.py:875\u001b[0m, in \u001b[0;36mBaseSearchCV.fit.<locals>.evaluate_candidates\u001b[0;34m(candidate_params, cv, more_results)\u001b[0m\n\u001b[1;32m    868\u001b[0m \u001b[38;5;28;01melif\u001b[39;00m \u001b[38;5;28mlen\u001b[39m(out) \u001b[38;5;241m!=\u001b[39m n_candidates \u001b[38;5;241m*\u001b[39m n_splits:\n\u001b[1;32m    869\u001b[0m     \u001b[38;5;28;01mraise\u001b[39;00m \u001b[38;5;167;01mValueError\u001b[39;00m(\n\u001b[1;32m    870\u001b[0m         \u001b[38;5;124m\"\u001b[39m\u001b[38;5;124mcv.split and cv.get_n_splits returned \u001b[39m\u001b[38;5;124m\"\u001b[39m\n\u001b[1;32m    871\u001b[0m         \u001b[38;5;124m\"\u001b[39m\u001b[38;5;124minconsistent results. Expected \u001b[39m\u001b[38;5;132;01m{}\u001b[39;00m\u001b[38;5;124m \u001b[39m\u001b[38;5;124m\"\u001b[39m\n\u001b[1;32m    872\u001b[0m         \u001b[38;5;124m\"\u001b[39m\u001b[38;5;124msplits, got \u001b[39m\u001b[38;5;132;01m{}\u001b[39;00m\u001b[38;5;124m\"\u001b[39m\u001b[38;5;241m.\u001b[39mformat(n_splits, \u001b[38;5;28mlen\u001b[39m(out) \u001b[38;5;241m/\u001b[39m\u001b[38;5;241m/\u001b[39m n_candidates)\n\u001b[1;32m    873\u001b[0m     )\n\u001b[0;32m--> 875\u001b[0m \u001b[43m_warn_or_raise_about_fit_failures\u001b[49m\u001b[43m(\u001b[49m\u001b[43mout\u001b[49m\u001b[43m,\u001b[49m\u001b[43m \u001b[49m\u001b[38;5;28;43mself\u001b[39;49m\u001b[38;5;241;43m.\u001b[39;49m\u001b[43merror_score\u001b[49m\u001b[43m)\u001b[49m\n\u001b[1;32m    877\u001b[0m \u001b[38;5;66;03m# For callable self.scoring, the return type is only know after\u001b[39;00m\n\u001b[1;32m    878\u001b[0m \u001b[38;5;66;03m# calling. If the return type is a dictionary, the error scores\u001b[39;00m\n\u001b[1;32m    879\u001b[0m \u001b[38;5;66;03m# can now be inserted with the correct key. The type checking\u001b[39;00m\n\u001b[1;32m    880\u001b[0m \u001b[38;5;66;03m# of out will be done in `_insert_error_scores`.\u001b[39;00m\n\u001b[1;32m    881\u001b[0m \u001b[38;5;28;01mif\u001b[39;00m \u001b[38;5;28mcallable\u001b[39m(\u001b[38;5;28mself\u001b[39m\u001b[38;5;241m.\u001b[39mscoring):\n",
      "File \u001b[0;32m~/miniconda3/envs/DAA/lib/python3.10/site-packages/sklearn/model_selection/_validation.py:414\u001b[0m, in \u001b[0;36m_warn_or_raise_about_fit_failures\u001b[0;34m(results, error_score)\u001b[0m\n\u001b[1;32m    407\u001b[0m \u001b[38;5;28;01mif\u001b[39;00m num_failed_fits \u001b[38;5;241m==\u001b[39m num_fits:\n\u001b[1;32m    408\u001b[0m     all_fits_failed_message \u001b[38;5;241m=\u001b[39m (\n\u001b[1;32m    409\u001b[0m         \u001b[38;5;124mf\u001b[39m\u001b[38;5;124m\"\u001b[39m\u001b[38;5;130;01m\\n\u001b[39;00m\u001b[38;5;124mAll the \u001b[39m\u001b[38;5;132;01m{\u001b[39;00mnum_fits\u001b[38;5;132;01m}\u001b[39;00m\u001b[38;5;124m fits failed.\u001b[39m\u001b[38;5;130;01m\\n\u001b[39;00m\u001b[38;5;124m\"\u001b[39m\n\u001b[1;32m    410\u001b[0m         \u001b[38;5;124m\"\u001b[39m\u001b[38;5;124mIt is very likely that your model is misconfigured.\u001b[39m\u001b[38;5;130;01m\\n\u001b[39;00m\u001b[38;5;124m\"\u001b[39m\n\u001b[1;32m    411\u001b[0m         \u001b[38;5;124m\"\u001b[39m\u001b[38;5;124mYou can try to debug the error by setting error_score=\u001b[39m\u001b[38;5;124m'\u001b[39m\u001b[38;5;124mraise\u001b[39m\u001b[38;5;124m'\u001b[39m\u001b[38;5;124m.\u001b[39m\u001b[38;5;130;01m\\n\u001b[39;00m\u001b[38;5;130;01m\\n\u001b[39;00m\u001b[38;5;124m\"\u001b[39m\n\u001b[1;32m    412\u001b[0m         \u001b[38;5;124mf\u001b[39m\u001b[38;5;124m\"\u001b[39m\u001b[38;5;124mBelow are more details about the failures:\u001b[39m\u001b[38;5;130;01m\\n\u001b[39;00m\u001b[38;5;132;01m{\u001b[39;00mfit_errors_summary\u001b[38;5;132;01m}\u001b[39;00m\u001b[38;5;124m\"\u001b[39m\n\u001b[1;32m    413\u001b[0m     )\n\u001b[0;32m--> 414\u001b[0m     \u001b[38;5;28;01mraise\u001b[39;00m \u001b[38;5;167;01mValueError\u001b[39;00m(all_fits_failed_message)\n\u001b[1;32m    416\u001b[0m \u001b[38;5;28;01melse\u001b[39;00m:\n\u001b[1;32m    417\u001b[0m     some_fits_failed_message \u001b[38;5;241m=\u001b[39m (\n\u001b[1;32m    418\u001b[0m         \u001b[38;5;124mf\u001b[39m\u001b[38;5;124m\"\u001b[39m\u001b[38;5;130;01m\\n\u001b[39;00m\u001b[38;5;132;01m{\u001b[39;00mnum_failed_fits\u001b[38;5;132;01m}\u001b[39;00m\u001b[38;5;124m fits failed out of a total of \u001b[39m\u001b[38;5;132;01m{\u001b[39;00mnum_fits\u001b[38;5;132;01m}\u001b[39;00m\u001b[38;5;124m.\u001b[39m\u001b[38;5;130;01m\\n\u001b[39;00m\u001b[38;5;124m\"\u001b[39m\n\u001b[1;32m    419\u001b[0m         \u001b[38;5;124m\"\u001b[39m\u001b[38;5;124mThe score on these train-test partitions for these parameters\u001b[39m\u001b[38;5;124m\"\u001b[39m\n\u001b[0;32m   (...)\u001b[0m\n\u001b[1;32m    423\u001b[0m         \u001b[38;5;124mf\u001b[39m\u001b[38;5;124m\"\u001b[39m\u001b[38;5;124mBelow are more details about the failures:\u001b[39m\u001b[38;5;130;01m\\n\u001b[39;00m\u001b[38;5;132;01m{\u001b[39;00mfit_errors_summary\u001b[38;5;132;01m}\u001b[39;00m\u001b[38;5;124m\"\u001b[39m\n\u001b[1;32m    424\u001b[0m     )\n",
      "\u001b[0;31mValueError\u001b[0m: \nAll the 15 fits failed.\nIt is very likely that your model is misconfigured.\nYou can try to debug the error by setting error_score='raise'.\n\nBelow are more details about the failures:\n--------------------------------------------------------------------------------\n1 fits failed with the following error:\nTraceback (most recent call last):\n  File \"/home/joana/miniconda3/envs/DAA/lib/python3.10/site-packages/sklearn/model_selection/_validation.py\", line 732, in _fit_and_score\n    estimator.fit(X_train, y_train, **fit_params)\n  File \"/home/joana/miniconda3/envs/DAA/lib/python3.10/site-packages/scikeras/wrappers.py\", line 760, in fit\n    self._fit(\n  File \"/home/joana/miniconda3/envs/DAA/lib/python3.10/site-packages/scikeras/wrappers.py\", line 928, in _fit\n    self._fit_keras_model(\n  File \"/home/joana/miniconda3/envs/DAA/lib/python3.10/site-packages/scikeras/wrappers.py\", line 524, in _fit_keras_model\n    hist = self.model_.fit(x=X, y=y, **fit_args)\n  File \"/home/joana/miniconda3/envs/DAA/lib/python3.10/site-packages/keras/utils/traceback_utils.py\", line 70, in error_handler\n    raise e.with_traceback(filtered_tb) from None\n  File \"/tmp/__autograph_generated_file2s3docdx.py\", line 15, in tf__train_function\n    retval_ = ag__.converted_call(ag__.ld(step_function), (ag__.ld(self), ag__.ld(iterator)), None, fscope)\nValueError: in user code:\n\n    File \"/home/joana/miniconda3/envs/DAA/lib/python3.10/site-packages/keras/engine/training.py\", line 1284, in train_function  *\n        return step_function(self, iterator)\n    File \"/home/joana/miniconda3/envs/DAA/lib/python3.10/site-packages/keras/engine/training.py\", line 1268, in step_function  **\n        outputs = model.distribute_strategy.run(run_step, args=(data,))\n    File \"/home/joana/miniconda3/envs/DAA/lib/python3.10/site-packages/keras/engine/training.py\", line 1249, in run_step  **\n        outputs = model.train_step(data)\n    File \"/home/joana/miniconda3/envs/DAA/lib/python3.10/site-packages/keras/engine/training.py\", line 1050, in train_step\n        y_pred = self(x, training=True)\n    File \"/home/joana/miniconda3/envs/DAA/lib/python3.10/site-packages/keras/utils/traceback_utils.py\", line 70, in error_handler\n        raise e.with_traceback(filtered_tb) from None\n    File \"/home/joana/miniconda3/envs/DAA/lib/python3.10/site-packages/keras/engine/input_spec.py\", line 298, in assert_input_compatibility\n        raise ValueError(\n\n    ValueError: Input 0 of layer \"sequential_1\" is incompatible with the layer: expected shape=(None, 5), found shape=(None, 13)\n\n\n--------------------------------------------------------------------------------\n1 fits failed with the following error:\nTraceback (most recent call last):\n  File \"/home/joana/miniconda3/envs/DAA/lib/python3.10/site-packages/sklearn/model_selection/_validation.py\", line 732, in _fit_and_score\n    estimator.fit(X_train, y_train, **fit_params)\n  File \"/home/joana/miniconda3/envs/DAA/lib/python3.10/site-packages/scikeras/wrappers.py\", line 760, in fit\n    self._fit(\n  File \"/home/joana/miniconda3/envs/DAA/lib/python3.10/site-packages/scikeras/wrappers.py\", line 928, in _fit\n    self._fit_keras_model(\n  File \"/home/joana/miniconda3/envs/DAA/lib/python3.10/site-packages/scikeras/wrappers.py\", line 524, in _fit_keras_model\n    hist = self.model_.fit(x=X, y=y, **fit_args)\n  File \"/home/joana/miniconda3/envs/DAA/lib/python3.10/site-packages/keras/utils/traceback_utils.py\", line 70, in error_handler\n    raise e.with_traceback(filtered_tb) from None\n  File \"/tmp/__autograph_generated_file2s3docdx.py\", line 15, in tf__train_function\n    retval_ = ag__.converted_call(ag__.ld(step_function), (ag__.ld(self), ag__.ld(iterator)), None, fscope)\nValueError: in user code:\n\n    File \"/home/joana/miniconda3/envs/DAA/lib/python3.10/site-packages/keras/engine/training.py\", line 1284, in train_function  *\n        return step_function(self, iterator)\n    File \"/home/joana/miniconda3/envs/DAA/lib/python3.10/site-packages/keras/engine/training.py\", line 1268, in step_function  **\n        outputs = model.distribute_strategy.run(run_step, args=(data,))\n    File \"/home/joana/miniconda3/envs/DAA/lib/python3.10/site-packages/keras/engine/training.py\", line 1249, in run_step  **\n        outputs = model.train_step(data)\n    File \"/home/joana/miniconda3/envs/DAA/lib/python3.10/site-packages/keras/engine/training.py\", line 1050, in train_step\n        y_pred = self(x, training=True)\n    File \"/home/joana/miniconda3/envs/DAA/lib/python3.10/site-packages/keras/utils/traceback_utils.py\", line 70, in error_handler\n        raise e.with_traceback(filtered_tb) from None\n    File \"/home/joana/miniconda3/envs/DAA/lib/python3.10/site-packages/keras/engine/input_spec.py\", line 298, in assert_input_compatibility\n        raise ValueError(\n\n    ValueError: Input 0 of layer \"sequential_2\" is incompatible with the layer: expected shape=(None, 5), found shape=(None, 13)\n\n\n--------------------------------------------------------------------------------\n1 fits failed with the following error:\nTraceback (most recent call last):\n  File \"/home/joana/miniconda3/envs/DAA/lib/python3.10/site-packages/sklearn/model_selection/_validation.py\", line 732, in _fit_and_score\n    estimator.fit(X_train, y_train, **fit_params)\n  File \"/home/joana/miniconda3/envs/DAA/lib/python3.10/site-packages/scikeras/wrappers.py\", line 760, in fit\n    self._fit(\n  File \"/home/joana/miniconda3/envs/DAA/lib/python3.10/site-packages/scikeras/wrappers.py\", line 928, in _fit\n    self._fit_keras_model(\n  File \"/home/joana/miniconda3/envs/DAA/lib/python3.10/site-packages/scikeras/wrappers.py\", line 524, in _fit_keras_model\n    hist = self.model_.fit(x=X, y=y, **fit_args)\n  File \"/home/joana/miniconda3/envs/DAA/lib/python3.10/site-packages/keras/utils/traceback_utils.py\", line 70, in error_handler\n    raise e.with_traceback(filtered_tb) from None\n  File \"/tmp/__autograph_generated_file2s3docdx.py\", line 15, in tf__train_function\n    retval_ = ag__.converted_call(ag__.ld(step_function), (ag__.ld(self), ag__.ld(iterator)), None, fscope)\nValueError: in user code:\n\n    File \"/home/joana/miniconda3/envs/DAA/lib/python3.10/site-packages/keras/engine/training.py\", line 1284, in train_function  *\n        return step_function(self, iterator)\n    File \"/home/joana/miniconda3/envs/DAA/lib/python3.10/site-packages/keras/engine/training.py\", line 1268, in step_function  **\n        outputs = model.distribute_strategy.run(run_step, args=(data,))\n    File \"/home/joana/miniconda3/envs/DAA/lib/python3.10/site-packages/keras/engine/training.py\", line 1249, in run_step  **\n        outputs = model.train_step(data)\n    File \"/home/joana/miniconda3/envs/DAA/lib/python3.10/site-packages/keras/engine/training.py\", line 1050, in train_step\n        y_pred = self(x, training=True)\n    File \"/home/joana/miniconda3/envs/DAA/lib/python3.10/site-packages/keras/utils/traceback_utils.py\", line 70, in error_handler\n        raise e.with_traceback(filtered_tb) from None\n    File \"/home/joana/miniconda3/envs/DAA/lib/python3.10/site-packages/keras/engine/input_spec.py\", line 298, in assert_input_compatibility\n        raise ValueError(\n\n    ValueError: Input 0 of layer \"sequential_3\" is incompatible with the layer: expected shape=(None, 5), found shape=(None, 13)\n\n\n--------------------------------------------------------------------------------\n1 fits failed with the following error:\nTraceback (most recent call last):\n  File \"/home/joana/miniconda3/envs/DAA/lib/python3.10/site-packages/sklearn/model_selection/_validation.py\", line 732, in _fit_and_score\n    estimator.fit(X_train, y_train, **fit_params)\n  File \"/home/joana/miniconda3/envs/DAA/lib/python3.10/site-packages/scikeras/wrappers.py\", line 760, in fit\n    self._fit(\n  File \"/home/joana/miniconda3/envs/DAA/lib/python3.10/site-packages/scikeras/wrappers.py\", line 928, in _fit\n    self._fit_keras_model(\n  File \"/home/joana/miniconda3/envs/DAA/lib/python3.10/site-packages/scikeras/wrappers.py\", line 524, in _fit_keras_model\n    hist = self.model_.fit(x=X, y=y, **fit_args)\n  File \"/home/joana/miniconda3/envs/DAA/lib/python3.10/site-packages/keras/utils/traceback_utils.py\", line 70, in error_handler\n    raise e.with_traceback(filtered_tb) from None\n  File \"/tmp/__autograph_generated_file2s3docdx.py\", line 15, in tf__train_function\n    retval_ = ag__.converted_call(ag__.ld(step_function), (ag__.ld(self), ag__.ld(iterator)), None, fscope)\nValueError: in user code:\n\n    File \"/home/joana/miniconda3/envs/DAA/lib/python3.10/site-packages/keras/engine/training.py\", line 1284, in train_function  *\n        return step_function(self, iterator)\n    File \"/home/joana/miniconda3/envs/DAA/lib/python3.10/site-packages/keras/engine/training.py\", line 1268, in step_function  **\n        outputs = model.distribute_strategy.run(run_step, args=(data,))\n    File \"/home/joana/miniconda3/envs/DAA/lib/python3.10/site-packages/keras/engine/training.py\", line 1249, in run_step  **\n        outputs = model.train_step(data)\n    File \"/home/joana/miniconda3/envs/DAA/lib/python3.10/site-packages/keras/engine/training.py\", line 1050, in train_step\n        y_pred = self(x, training=True)\n    File \"/home/joana/miniconda3/envs/DAA/lib/python3.10/site-packages/keras/utils/traceback_utils.py\", line 70, in error_handler\n        raise e.with_traceback(filtered_tb) from None\n    File \"/home/joana/miniconda3/envs/DAA/lib/python3.10/site-packages/keras/engine/input_spec.py\", line 298, in assert_input_compatibility\n        raise ValueError(\n\n    ValueError: Input 0 of layer \"sequential_4\" is incompatible with the layer: expected shape=(None, 5), found shape=(None, 13)\n\n\n--------------------------------------------------------------------------------\n1 fits failed with the following error:\nTraceback (most recent call last):\n  File \"/home/joana/miniconda3/envs/DAA/lib/python3.10/site-packages/sklearn/model_selection/_validation.py\", line 732, in _fit_and_score\n    estimator.fit(X_train, y_train, **fit_params)\n  File \"/home/joana/miniconda3/envs/DAA/lib/python3.10/site-packages/scikeras/wrappers.py\", line 760, in fit\n    self._fit(\n  File \"/home/joana/miniconda3/envs/DAA/lib/python3.10/site-packages/scikeras/wrappers.py\", line 928, in _fit\n    self._fit_keras_model(\n  File \"/home/joana/miniconda3/envs/DAA/lib/python3.10/site-packages/scikeras/wrappers.py\", line 524, in _fit_keras_model\n    hist = self.model_.fit(x=X, y=y, **fit_args)\n  File \"/home/joana/miniconda3/envs/DAA/lib/python3.10/site-packages/keras/utils/traceback_utils.py\", line 70, in error_handler\n    raise e.with_traceback(filtered_tb) from None\n  File \"/tmp/__autograph_generated_file2s3docdx.py\", line 15, in tf__train_function\n    retval_ = ag__.converted_call(ag__.ld(step_function), (ag__.ld(self), ag__.ld(iterator)), None, fscope)\nValueError: in user code:\n\n    File \"/home/joana/miniconda3/envs/DAA/lib/python3.10/site-packages/keras/engine/training.py\", line 1284, in train_function  *\n        return step_function(self, iterator)\n    File \"/home/joana/miniconda3/envs/DAA/lib/python3.10/site-packages/keras/engine/training.py\", line 1268, in step_function  **\n        outputs = model.distribute_strategy.run(run_step, args=(data,))\n    File \"/home/joana/miniconda3/envs/DAA/lib/python3.10/site-packages/keras/engine/training.py\", line 1249, in run_step  **\n        outputs = model.train_step(data)\n    File \"/home/joana/miniconda3/envs/DAA/lib/python3.10/site-packages/keras/engine/training.py\", line 1050, in train_step\n        y_pred = self(x, training=True)\n    File \"/home/joana/miniconda3/envs/DAA/lib/python3.10/site-packages/keras/utils/traceback_utils.py\", line 70, in error_handler\n        raise e.with_traceback(filtered_tb) from None\n    File \"/home/joana/miniconda3/envs/DAA/lib/python3.10/site-packages/keras/engine/input_spec.py\", line 298, in assert_input_compatibility\n        raise ValueError(\n\n    ValueError: Input 0 of layer \"sequential_5\" is incompatible with the layer: expected shape=(None, 5), found shape=(None, 13)\n\n\n--------------------------------------------------------------------------------\n1 fits failed with the following error:\nTraceback (most recent call last):\n  File \"/home/joana/miniconda3/envs/DAA/lib/python3.10/site-packages/sklearn/model_selection/_validation.py\", line 732, in _fit_and_score\n    estimator.fit(X_train, y_train, **fit_params)\n  File \"/home/joana/miniconda3/envs/DAA/lib/python3.10/site-packages/scikeras/wrappers.py\", line 760, in fit\n    self._fit(\n  File \"/home/joana/miniconda3/envs/DAA/lib/python3.10/site-packages/scikeras/wrappers.py\", line 928, in _fit\n    self._fit_keras_model(\n  File \"/home/joana/miniconda3/envs/DAA/lib/python3.10/site-packages/scikeras/wrappers.py\", line 524, in _fit_keras_model\n    hist = self.model_.fit(x=X, y=y, **fit_args)\n  File \"/home/joana/miniconda3/envs/DAA/lib/python3.10/site-packages/keras/utils/traceback_utils.py\", line 70, in error_handler\n    raise e.with_traceback(filtered_tb) from None\n  File \"/tmp/__autograph_generated_file2s3docdx.py\", line 15, in tf__train_function\n    retval_ = ag__.converted_call(ag__.ld(step_function), (ag__.ld(self), ag__.ld(iterator)), None, fscope)\nValueError: in user code:\n\n    File \"/home/joana/miniconda3/envs/DAA/lib/python3.10/site-packages/keras/engine/training.py\", line 1284, in train_function  *\n        return step_function(self, iterator)\n    File \"/home/joana/miniconda3/envs/DAA/lib/python3.10/site-packages/keras/engine/training.py\", line 1268, in step_function  **\n        outputs = model.distribute_strategy.run(run_step, args=(data,))\n    File \"/home/joana/miniconda3/envs/DAA/lib/python3.10/site-packages/keras/engine/training.py\", line 1249, in run_step  **\n        outputs = model.train_step(data)\n    File \"/home/joana/miniconda3/envs/DAA/lib/python3.10/site-packages/keras/engine/training.py\", line 1050, in train_step\n        y_pred = self(x, training=True)\n    File \"/home/joana/miniconda3/envs/DAA/lib/python3.10/site-packages/keras/utils/traceback_utils.py\", line 70, in error_handler\n        raise e.with_traceback(filtered_tb) from None\n    File \"/home/joana/miniconda3/envs/DAA/lib/python3.10/site-packages/keras/engine/input_spec.py\", line 298, in assert_input_compatibility\n        raise ValueError(\n\n    ValueError: Input 0 of layer \"sequential_6\" is incompatible with the layer: expected shape=(None, 5), found shape=(None, 13)\n\n\n--------------------------------------------------------------------------------\n1 fits failed with the following error:\nTraceback (most recent call last):\n  File \"/home/joana/miniconda3/envs/DAA/lib/python3.10/site-packages/sklearn/model_selection/_validation.py\", line 732, in _fit_and_score\n    estimator.fit(X_train, y_train, **fit_params)\n  File \"/home/joana/miniconda3/envs/DAA/lib/python3.10/site-packages/scikeras/wrappers.py\", line 760, in fit\n    self._fit(\n  File \"/home/joana/miniconda3/envs/DAA/lib/python3.10/site-packages/scikeras/wrappers.py\", line 928, in _fit\n    self._fit_keras_model(\n  File \"/home/joana/miniconda3/envs/DAA/lib/python3.10/site-packages/scikeras/wrappers.py\", line 524, in _fit_keras_model\n    hist = self.model_.fit(x=X, y=y, **fit_args)\n  File \"/home/joana/miniconda3/envs/DAA/lib/python3.10/site-packages/keras/utils/traceback_utils.py\", line 70, in error_handler\n    raise e.with_traceback(filtered_tb) from None\n  File \"/tmp/__autograph_generated_file2s3docdx.py\", line 15, in tf__train_function\n    retval_ = ag__.converted_call(ag__.ld(step_function), (ag__.ld(self), ag__.ld(iterator)), None, fscope)\nValueError: in user code:\n\n    File \"/home/joana/miniconda3/envs/DAA/lib/python3.10/site-packages/keras/engine/training.py\", line 1284, in train_function  *\n        return step_function(self, iterator)\n    File \"/home/joana/miniconda3/envs/DAA/lib/python3.10/site-packages/keras/engine/training.py\", line 1268, in step_function  **\n        outputs = model.distribute_strategy.run(run_step, args=(data,))\n    File \"/home/joana/miniconda3/envs/DAA/lib/python3.10/site-packages/keras/engine/training.py\", line 1249, in run_step  **\n        outputs = model.train_step(data)\n    File \"/home/joana/miniconda3/envs/DAA/lib/python3.10/site-packages/keras/engine/training.py\", line 1050, in train_step\n        y_pred = self(x, training=True)\n    File \"/home/joana/miniconda3/envs/DAA/lib/python3.10/site-packages/keras/utils/traceback_utils.py\", line 70, in error_handler\n        raise e.with_traceback(filtered_tb) from None\n    File \"/home/joana/miniconda3/envs/DAA/lib/python3.10/site-packages/keras/engine/input_spec.py\", line 298, in assert_input_compatibility\n        raise ValueError(\n\n    ValueError: Input 0 of layer \"sequential_7\" is incompatible with the layer: expected shape=(None, 5), found shape=(None, 13)\n\n\n--------------------------------------------------------------------------------\n1 fits failed with the following error:\nTraceback (most recent call last):\n  File \"/home/joana/miniconda3/envs/DAA/lib/python3.10/site-packages/sklearn/model_selection/_validation.py\", line 732, in _fit_and_score\n    estimator.fit(X_train, y_train, **fit_params)\n  File \"/home/joana/miniconda3/envs/DAA/lib/python3.10/site-packages/scikeras/wrappers.py\", line 760, in fit\n    self._fit(\n  File \"/home/joana/miniconda3/envs/DAA/lib/python3.10/site-packages/scikeras/wrappers.py\", line 928, in _fit\n    self._fit_keras_model(\n  File \"/home/joana/miniconda3/envs/DAA/lib/python3.10/site-packages/scikeras/wrappers.py\", line 524, in _fit_keras_model\n    hist = self.model_.fit(x=X, y=y, **fit_args)\n  File \"/home/joana/miniconda3/envs/DAA/lib/python3.10/site-packages/keras/utils/traceback_utils.py\", line 70, in error_handler\n    raise e.with_traceback(filtered_tb) from None\n  File \"/tmp/__autograph_generated_file2s3docdx.py\", line 15, in tf__train_function\n    retval_ = ag__.converted_call(ag__.ld(step_function), (ag__.ld(self), ag__.ld(iterator)), None, fscope)\nValueError: in user code:\n\n    File \"/home/joana/miniconda3/envs/DAA/lib/python3.10/site-packages/keras/engine/training.py\", line 1284, in train_function  *\n        return step_function(self, iterator)\n    File \"/home/joana/miniconda3/envs/DAA/lib/python3.10/site-packages/keras/engine/training.py\", line 1268, in step_function  **\n        outputs = model.distribute_strategy.run(run_step, args=(data,))\n    File \"/home/joana/miniconda3/envs/DAA/lib/python3.10/site-packages/keras/engine/training.py\", line 1249, in run_step  **\n        outputs = model.train_step(data)\n    File \"/home/joana/miniconda3/envs/DAA/lib/python3.10/site-packages/keras/engine/training.py\", line 1050, in train_step\n        y_pred = self(x, training=True)\n    File \"/home/joana/miniconda3/envs/DAA/lib/python3.10/site-packages/keras/utils/traceback_utils.py\", line 70, in error_handler\n        raise e.with_traceback(filtered_tb) from None\n    File \"/home/joana/miniconda3/envs/DAA/lib/python3.10/site-packages/keras/engine/input_spec.py\", line 298, in assert_input_compatibility\n        raise ValueError(\n\n    ValueError: Input 0 of layer \"sequential_8\" is incompatible with the layer: expected shape=(None, 5), found shape=(None, 13)\n\n\n--------------------------------------------------------------------------------\n1 fits failed with the following error:\nTraceback (most recent call last):\n  File \"/home/joana/miniconda3/envs/DAA/lib/python3.10/site-packages/sklearn/model_selection/_validation.py\", line 732, in _fit_and_score\n    estimator.fit(X_train, y_train, **fit_params)\n  File \"/home/joana/miniconda3/envs/DAA/lib/python3.10/site-packages/scikeras/wrappers.py\", line 760, in fit\n    self._fit(\n  File \"/home/joana/miniconda3/envs/DAA/lib/python3.10/site-packages/scikeras/wrappers.py\", line 928, in _fit\n    self._fit_keras_model(\n  File \"/home/joana/miniconda3/envs/DAA/lib/python3.10/site-packages/scikeras/wrappers.py\", line 524, in _fit_keras_model\n    hist = self.model_.fit(x=X, y=y, **fit_args)\n  File \"/home/joana/miniconda3/envs/DAA/lib/python3.10/site-packages/keras/utils/traceback_utils.py\", line 70, in error_handler\n    raise e.with_traceback(filtered_tb) from None\n  File \"/tmp/__autograph_generated_file2s3docdx.py\", line 15, in tf__train_function\n    retval_ = ag__.converted_call(ag__.ld(step_function), (ag__.ld(self), ag__.ld(iterator)), None, fscope)\nValueError: in user code:\n\n    File \"/home/joana/miniconda3/envs/DAA/lib/python3.10/site-packages/keras/engine/training.py\", line 1284, in train_function  *\n        return step_function(self, iterator)\n    File \"/home/joana/miniconda3/envs/DAA/lib/python3.10/site-packages/keras/engine/training.py\", line 1268, in step_function  **\n        outputs = model.distribute_strategy.run(run_step, args=(data,))\n    File \"/home/joana/miniconda3/envs/DAA/lib/python3.10/site-packages/keras/engine/training.py\", line 1249, in run_step  **\n        outputs = model.train_step(data)\n    File \"/home/joana/miniconda3/envs/DAA/lib/python3.10/site-packages/keras/engine/training.py\", line 1050, in train_step\n        y_pred = self(x, training=True)\n    File \"/home/joana/miniconda3/envs/DAA/lib/python3.10/site-packages/keras/utils/traceback_utils.py\", line 70, in error_handler\n        raise e.with_traceback(filtered_tb) from None\n    File \"/home/joana/miniconda3/envs/DAA/lib/python3.10/site-packages/keras/engine/input_spec.py\", line 298, in assert_input_compatibility\n        raise ValueError(\n\n    ValueError: Input 0 of layer \"sequential_9\" is incompatible with the layer: expected shape=(None, 5), found shape=(None, 13)\n\n\n--------------------------------------------------------------------------------\n1 fits failed with the following error:\nTraceback (most recent call last):\n  File \"/home/joana/miniconda3/envs/DAA/lib/python3.10/site-packages/sklearn/model_selection/_validation.py\", line 732, in _fit_and_score\n    estimator.fit(X_train, y_train, **fit_params)\n  File \"/home/joana/miniconda3/envs/DAA/lib/python3.10/site-packages/scikeras/wrappers.py\", line 760, in fit\n    self._fit(\n  File \"/home/joana/miniconda3/envs/DAA/lib/python3.10/site-packages/scikeras/wrappers.py\", line 928, in _fit\n    self._fit_keras_model(\n  File \"/home/joana/miniconda3/envs/DAA/lib/python3.10/site-packages/scikeras/wrappers.py\", line 524, in _fit_keras_model\n    hist = self.model_.fit(x=X, y=y, **fit_args)\n  File \"/home/joana/miniconda3/envs/DAA/lib/python3.10/site-packages/keras/utils/traceback_utils.py\", line 70, in error_handler\n    raise e.with_traceback(filtered_tb) from None\n  File \"/tmp/__autograph_generated_file2s3docdx.py\", line 15, in tf__train_function\n    retval_ = ag__.converted_call(ag__.ld(step_function), (ag__.ld(self), ag__.ld(iterator)), None, fscope)\nValueError: in user code:\n\n    File \"/home/joana/miniconda3/envs/DAA/lib/python3.10/site-packages/keras/engine/training.py\", line 1284, in train_function  *\n        return step_function(self, iterator)\n    File \"/home/joana/miniconda3/envs/DAA/lib/python3.10/site-packages/keras/engine/training.py\", line 1268, in step_function  **\n        outputs = model.distribute_strategy.run(run_step, args=(data,))\n    File \"/home/joana/miniconda3/envs/DAA/lib/python3.10/site-packages/keras/engine/training.py\", line 1249, in run_step  **\n        outputs = model.train_step(data)\n    File \"/home/joana/miniconda3/envs/DAA/lib/python3.10/site-packages/keras/engine/training.py\", line 1050, in train_step\n        y_pred = self(x, training=True)\n    File \"/home/joana/miniconda3/envs/DAA/lib/python3.10/site-packages/keras/utils/traceback_utils.py\", line 70, in error_handler\n        raise e.with_traceback(filtered_tb) from None\n    File \"/home/joana/miniconda3/envs/DAA/lib/python3.10/site-packages/keras/engine/input_spec.py\", line 298, in assert_input_compatibility\n        raise ValueError(\n\n    ValueError: Input 0 of layer \"sequential_10\" is incompatible with the layer: expected shape=(None, 5), found shape=(None, 13)\n\n\n--------------------------------------------------------------------------------\n1 fits failed with the following error:\nTraceback (most recent call last):\n  File \"/home/joana/miniconda3/envs/DAA/lib/python3.10/site-packages/sklearn/model_selection/_validation.py\", line 732, in _fit_and_score\n    estimator.fit(X_train, y_train, **fit_params)\n  File \"/home/joana/miniconda3/envs/DAA/lib/python3.10/site-packages/scikeras/wrappers.py\", line 760, in fit\n    self._fit(\n  File \"/home/joana/miniconda3/envs/DAA/lib/python3.10/site-packages/scikeras/wrappers.py\", line 928, in _fit\n    self._fit_keras_model(\n  File \"/home/joana/miniconda3/envs/DAA/lib/python3.10/site-packages/scikeras/wrappers.py\", line 524, in _fit_keras_model\n    hist = self.model_.fit(x=X, y=y, **fit_args)\n  File \"/home/joana/miniconda3/envs/DAA/lib/python3.10/site-packages/keras/utils/traceback_utils.py\", line 70, in error_handler\n    raise e.with_traceback(filtered_tb) from None\n  File \"/tmp/__autograph_generated_file2s3docdx.py\", line 15, in tf__train_function\n    retval_ = ag__.converted_call(ag__.ld(step_function), (ag__.ld(self), ag__.ld(iterator)), None, fscope)\nValueError: in user code:\n\n    File \"/home/joana/miniconda3/envs/DAA/lib/python3.10/site-packages/keras/engine/training.py\", line 1284, in train_function  *\n        return step_function(self, iterator)\n    File \"/home/joana/miniconda3/envs/DAA/lib/python3.10/site-packages/keras/engine/training.py\", line 1268, in step_function  **\n        outputs = model.distribute_strategy.run(run_step, args=(data,))\n    File \"/home/joana/miniconda3/envs/DAA/lib/python3.10/site-packages/keras/engine/training.py\", line 1249, in run_step  **\n        outputs = model.train_step(data)\n    File \"/home/joana/miniconda3/envs/DAA/lib/python3.10/site-packages/keras/engine/training.py\", line 1050, in train_step\n        y_pred = self(x, training=True)\n    File \"/home/joana/miniconda3/envs/DAA/lib/python3.10/site-packages/keras/utils/traceback_utils.py\", line 70, in error_handler\n        raise e.with_traceback(filtered_tb) from None\n    File \"/home/joana/miniconda3/envs/DAA/lib/python3.10/site-packages/keras/engine/input_spec.py\", line 298, in assert_input_compatibility\n        raise ValueError(\n\n    ValueError: Input 0 of layer \"sequential_11\" is incompatible with the layer: expected shape=(None, 5), found shape=(None, 13)\n\n\n--------------------------------------------------------------------------------\n1 fits failed with the following error:\nTraceback (most recent call last):\n  File \"/home/joana/miniconda3/envs/DAA/lib/python3.10/site-packages/sklearn/model_selection/_validation.py\", line 732, in _fit_and_score\n    estimator.fit(X_train, y_train, **fit_params)\n  File \"/home/joana/miniconda3/envs/DAA/lib/python3.10/site-packages/scikeras/wrappers.py\", line 760, in fit\n    self._fit(\n  File \"/home/joana/miniconda3/envs/DAA/lib/python3.10/site-packages/scikeras/wrappers.py\", line 928, in _fit\n    self._fit_keras_model(\n  File \"/home/joana/miniconda3/envs/DAA/lib/python3.10/site-packages/scikeras/wrappers.py\", line 524, in _fit_keras_model\n    hist = self.model_.fit(x=X, y=y, **fit_args)\n  File \"/home/joana/miniconda3/envs/DAA/lib/python3.10/site-packages/keras/utils/traceback_utils.py\", line 70, in error_handler\n    raise e.with_traceback(filtered_tb) from None\n  File \"/tmp/__autograph_generated_file2s3docdx.py\", line 15, in tf__train_function\n    retval_ = ag__.converted_call(ag__.ld(step_function), (ag__.ld(self), ag__.ld(iterator)), None, fscope)\nValueError: in user code:\n\n    File \"/home/joana/miniconda3/envs/DAA/lib/python3.10/site-packages/keras/engine/training.py\", line 1284, in train_function  *\n        return step_function(self, iterator)\n    File \"/home/joana/miniconda3/envs/DAA/lib/python3.10/site-packages/keras/engine/training.py\", line 1268, in step_function  **\n        outputs = model.distribute_strategy.run(run_step, args=(data,))\n    File \"/home/joana/miniconda3/envs/DAA/lib/python3.10/site-packages/keras/engine/training.py\", line 1249, in run_step  **\n        outputs = model.train_step(data)\n    File \"/home/joana/miniconda3/envs/DAA/lib/python3.10/site-packages/keras/engine/training.py\", line 1050, in train_step\n        y_pred = self(x, training=True)\n    File \"/home/joana/miniconda3/envs/DAA/lib/python3.10/site-packages/keras/utils/traceback_utils.py\", line 70, in error_handler\n        raise e.with_traceback(filtered_tb) from None\n    File \"/home/joana/miniconda3/envs/DAA/lib/python3.10/site-packages/keras/engine/input_spec.py\", line 298, in assert_input_compatibility\n        raise ValueError(\n\n    ValueError: Input 0 of layer \"sequential_12\" is incompatible with the layer: expected shape=(None, 5), found shape=(None, 13)\n\n\n--------------------------------------------------------------------------------\n1 fits failed with the following error:\nTraceback (most recent call last):\n  File \"/home/joana/miniconda3/envs/DAA/lib/python3.10/site-packages/sklearn/model_selection/_validation.py\", line 732, in _fit_and_score\n    estimator.fit(X_train, y_train, **fit_params)\n  File \"/home/joana/miniconda3/envs/DAA/lib/python3.10/site-packages/scikeras/wrappers.py\", line 760, in fit\n    self._fit(\n  File \"/home/joana/miniconda3/envs/DAA/lib/python3.10/site-packages/scikeras/wrappers.py\", line 928, in _fit\n    self._fit_keras_model(\n  File \"/home/joana/miniconda3/envs/DAA/lib/python3.10/site-packages/scikeras/wrappers.py\", line 524, in _fit_keras_model\n    hist = self.model_.fit(x=X, y=y, **fit_args)\n  File \"/home/joana/miniconda3/envs/DAA/lib/python3.10/site-packages/keras/utils/traceback_utils.py\", line 70, in error_handler\n    raise e.with_traceback(filtered_tb) from None\n  File \"/tmp/__autograph_generated_file2s3docdx.py\", line 15, in tf__train_function\n    retval_ = ag__.converted_call(ag__.ld(step_function), (ag__.ld(self), ag__.ld(iterator)), None, fscope)\nValueError: in user code:\n\n    File \"/home/joana/miniconda3/envs/DAA/lib/python3.10/site-packages/keras/engine/training.py\", line 1284, in train_function  *\n        return step_function(self, iterator)\n    File \"/home/joana/miniconda3/envs/DAA/lib/python3.10/site-packages/keras/engine/training.py\", line 1268, in step_function  **\n        outputs = model.distribute_strategy.run(run_step, args=(data,))\n    File \"/home/joana/miniconda3/envs/DAA/lib/python3.10/site-packages/keras/engine/training.py\", line 1249, in run_step  **\n        outputs = model.train_step(data)\n    File \"/home/joana/miniconda3/envs/DAA/lib/python3.10/site-packages/keras/engine/training.py\", line 1050, in train_step\n        y_pred = self(x, training=True)\n    File \"/home/joana/miniconda3/envs/DAA/lib/python3.10/site-packages/keras/utils/traceback_utils.py\", line 70, in error_handler\n        raise e.with_traceback(filtered_tb) from None\n    File \"/home/joana/miniconda3/envs/DAA/lib/python3.10/site-packages/keras/engine/input_spec.py\", line 298, in assert_input_compatibility\n        raise ValueError(\n\n    ValueError: Input 0 of layer \"sequential_13\" is incompatible with the layer: expected shape=(None, 5), found shape=(None, 13)\n\n\n--------------------------------------------------------------------------------\n1 fits failed with the following error:\nTraceback (most recent call last):\n  File \"/home/joana/miniconda3/envs/DAA/lib/python3.10/site-packages/sklearn/model_selection/_validation.py\", line 732, in _fit_and_score\n    estimator.fit(X_train, y_train, **fit_params)\n  File \"/home/joana/miniconda3/envs/DAA/lib/python3.10/site-packages/scikeras/wrappers.py\", line 760, in fit\n    self._fit(\n  File \"/home/joana/miniconda3/envs/DAA/lib/python3.10/site-packages/scikeras/wrappers.py\", line 928, in _fit\n    self._fit_keras_model(\n  File \"/home/joana/miniconda3/envs/DAA/lib/python3.10/site-packages/scikeras/wrappers.py\", line 524, in _fit_keras_model\n    hist = self.model_.fit(x=X, y=y, **fit_args)\n  File \"/home/joana/miniconda3/envs/DAA/lib/python3.10/site-packages/keras/utils/traceback_utils.py\", line 70, in error_handler\n    raise e.with_traceback(filtered_tb) from None\n  File \"/tmp/__autograph_generated_file2s3docdx.py\", line 15, in tf__train_function\n    retval_ = ag__.converted_call(ag__.ld(step_function), (ag__.ld(self), ag__.ld(iterator)), None, fscope)\nValueError: in user code:\n\n    File \"/home/joana/miniconda3/envs/DAA/lib/python3.10/site-packages/keras/engine/training.py\", line 1284, in train_function  *\n        return step_function(self, iterator)\n    File \"/home/joana/miniconda3/envs/DAA/lib/python3.10/site-packages/keras/engine/training.py\", line 1268, in step_function  **\n        outputs = model.distribute_strategy.run(run_step, args=(data,))\n    File \"/home/joana/miniconda3/envs/DAA/lib/python3.10/site-packages/keras/engine/training.py\", line 1249, in run_step  **\n        outputs = model.train_step(data)\n    File \"/home/joana/miniconda3/envs/DAA/lib/python3.10/site-packages/keras/engine/training.py\", line 1050, in train_step\n        y_pred = self(x, training=True)\n    File \"/home/joana/miniconda3/envs/DAA/lib/python3.10/site-packages/keras/utils/traceback_utils.py\", line 70, in error_handler\n        raise e.with_traceback(filtered_tb) from None\n    File \"/home/joana/miniconda3/envs/DAA/lib/python3.10/site-packages/keras/engine/input_spec.py\", line 298, in assert_input_compatibility\n        raise ValueError(\n\n    ValueError: Input 0 of layer \"sequential_14\" is incompatible with the layer: expected shape=(None, 5), found shape=(None, 13)\n\n\n--------------------------------------------------------------------------------\n1 fits failed with the following error:\nTraceback (most recent call last):\n  File \"/home/joana/miniconda3/envs/DAA/lib/python3.10/site-packages/sklearn/model_selection/_validation.py\", line 732, in _fit_and_score\n    estimator.fit(X_train, y_train, **fit_params)\n  File \"/home/joana/miniconda3/envs/DAA/lib/python3.10/site-packages/scikeras/wrappers.py\", line 760, in fit\n    self._fit(\n  File \"/home/joana/miniconda3/envs/DAA/lib/python3.10/site-packages/scikeras/wrappers.py\", line 928, in _fit\n    self._fit_keras_model(\n  File \"/home/joana/miniconda3/envs/DAA/lib/python3.10/site-packages/scikeras/wrappers.py\", line 524, in _fit_keras_model\n    hist = self.model_.fit(x=X, y=y, **fit_args)\n  File \"/home/joana/miniconda3/envs/DAA/lib/python3.10/site-packages/keras/utils/traceback_utils.py\", line 70, in error_handler\n    raise e.with_traceback(filtered_tb) from None\n  File \"/tmp/__autograph_generated_file2s3docdx.py\", line 15, in tf__train_function\n    retval_ = ag__.converted_call(ag__.ld(step_function), (ag__.ld(self), ag__.ld(iterator)), None, fscope)\nValueError: in user code:\n\n    File \"/home/joana/miniconda3/envs/DAA/lib/python3.10/site-packages/keras/engine/training.py\", line 1284, in train_function  *\n        return step_function(self, iterator)\n    File \"/home/joana/miniconda3/envs/DAA/lib/python3.10/site-packages/keras/engine/training.py\", line 1268, in step_function  **\n        outputs = model.distribute_strategy.run(run_step, args=(data,))\n    File \"/home/joana/miniconda3/envs/DAA/lib/python3.10/site-packages/keras/engine/training.py\", line 1249, in run_step  **\n        outputs = model.train_step(data)\n    File \"/home/joana/miniconda3/envs/DAA/lib/python3.10/site-packages/keras/engine/training.py\", line 1050, in train_step\n        y_pred = self(x, training=True)\n    File \"/home/joana/miniconda3/envs/DAA/lib/python3.10/site-packages/keras/utils/traceback_utils.py\", line 70, in error_handler\n        raise e.with_traceback(filtered_tb) from None\n    File \"/home/joana/miniconda3/envs/DAA/lib/python3.10/site-packages/keras/engine/input_spec.py\", line 298, in assert_input_compatibility\n        raise ValueError(\n\n    ValueError: Input 0 of layer \"sequential_15\" is incompatible with the layer: expected shape=(None, 5), found shape=(None, 13)\n\n"
     ]
    }
   ],
   "source": [
    "grid_search.fit(X_train, y_train)"
   ]
  },
  {
   "cell_type": "code",
   "execution_count": null,
   "id": "5f848680-912e-4e23-b229-5a0128c3cd36",
   "metadata": {},
   "outputs": [],
   "source": [
    "print(\"Best: %f using %s\" % (grid_search.best_score_, grid_search.best_params_))"
   ]
  },
  {
   "cell_type": "code",
   "execution_count": null,
   "id": "48063f30-0713-4492-b5dc-132e7a760d14",
   "metadata": {},
   "outputs": [],
   "source": [
    "means = grid_search.cv_results_['mean_test_score']\n",
    "stds = grid_search.cv_results_['std_test_score']\n",
    "params = grid_search.cv_results_['params']"
   ]
  },
  {
   "cell_type": "code",
   "execution_count": null,
   "id": "b28b2b3e-2037-4b92-b9f5-00d8e820e288",
   "metadata": {},
   "outputs": [],
   "source": [
    "for mean, stdev, param in zip(means, stds, params):\n",
    "    print(\"%f (%f) with: %r\" % (mean, stdev, param))"
   ]
  },
  {
   "cell_type": "code",
   "execution_count": null,
   "id": "efd5e442-9a06-4c16-b818-e11437f8099a",
   "metadata": {},
   "outputs": [],
   "source": [
    "best_mlp_model = grid_search.best_estimator_\n",
    "print(best_mlp_model)"
   ]
  },
  {
   "cell_type": "code",
   "execution_count": null,
   "id": "94320efd-976a-475c-8563-2dd88fdb7c15",
   "metadata": {},
   "outputs": [],
   "source": [
    "best_mlp_model.fit(X_train, y_train, epochs = 20, validation_data = (X_test, y_test), verbose = 1)"
   ]
  },
  {
   "cell_type": "code",
   "execution_count": null,
   "id": "a3bdc7ed-297a-4d3a-b07f-ff1b052e0a9b",
   "metadata": {
    "tags": []
   },
   "outputs": [],
   "source": [
    "plt.plot(best_mlp_model.history_['loss'])\n",
    "plt.plot(best_mlp_model.history_['val_loss'])\n",
    "plt.title('model performance')\n",
    "plt.ylabel('loss values')\n",
    "plt.xlabel('epoch')\n",
    "plt.legend(['train', 'val'], loc='upper left')\n",
    "plt.show()"
   ]
  }
 ],
 "metadata": {
  "kernelspec": {
   "display_name": "Python 3 (ipykernel)",
   "language": "python",
   "name": "python3"
  },
  "language_info": {
   "codemirror_mode": {
    "name": "ipython",
    "version": 3
   },
   "file_extension": ".py",
   "mimetype": "text/x-python",
   "name": "python",
   "nbconvert_exporter": "python",
   "pygments_lexer": "ipython3",
   "version": "3.11.6"
  }
 },
 "nbformat": 4,
 "nbformat_minor": 5
}
